Workbook

Sheet ข้อมูล
B2: ข้อมูลนักเรียน | C2: ชั้นประถมศึกษาปีที่ 3 | D2: โรงเรียน.
A4: ที่ | B4: เลขประจำตัว | C4: ชื่อ - นามสกุล | D4: เพศ | E4: วัน เดือน ปี เกิด
A5: 1 | B5: 1575 | C5: ด.ช. ห้องเรียน วิชาการ | D5: ชาย | E5: 39818
A6: 2 | B6: 1576 | C6: ด.ช. ห้องเรียน วิชาการ | D6: ชาย | E6: 39942
A7: 3 | B7: 1577 | C7: ด.ช. ห้องเรียน วิชาการ | D7: ชาย | E7: 39475
A8: 4 | B8: 1579 | C8: ด.ช. ห้องเรียน วิชาการ | D8: ชาย | E8: 39895
A9: 5 | B9: 1581 | C9: ด.ช. ห้องเรียน วิชาการ | D9: ชาย | E9: 39880
A10: 6 | B10: 1582 | C10: ด.ช. ห้องเรียน วิชาการ | D10: ชาย | E10: 39735
A11: 7 | B11: 1584 | C11: ด.ช. ห้องเรียน วิชาการ | D11: ชาย | E11: 39767
A12: 8 | B12: 1585 | C12: ด.ช. ห้องเรียน วิชาการ | D12: ชาย | E12: 39612
A13: 9 | B13: 1586 | C13: ด.ช. ห้องเรียน วิชาการ | D13: ชาย | E13: 39930
A14: 10 | B14: 1589 | C14: ด.ญ.ห้องเรียน วิชาการ | D14: หญิง | E14: 39687
A15: 11 | B15: 1713 | C15: ด.ญ.ห้องเรียน วิชาการ | D15: หญิง | E15: 39234
A16: 12 | B16: 1714 | C16: ด.ญ.ห้องเรียน วิชาการ | D16: หญิง | E16: 38997
... A21: 17 | B21: 1718 | C21: ด.ญ.ห้องเรียน วิชาการ | D21: หญิง | E21: 39863
A22: 18 | E22: 39864
A23: 19 | E23: 39865
A24: 20 | E24: 39866
A25: 21 | E25: 39867
A26: 22 | E26: 39868
A27: 23 | E27: 39869
A28: 24 | E28: 39870
A29: 25 | E29: 39871
A30: 26 | E30: 39872
A31: 27 | E31: 39873
A32: 28 | E32: 39874
A33: 29 | E33: 39875
A34: 30 | E34: 39876

Sheet พ.ค.
A2: แบบบันทึกน้ำหนัก - ส่วนสูง ชั้นมัธยมศึกษาปีที่ 3 โรงเรียน.......................... ปีการศึกษา 2566
A3: ประจำเดือน พฤษภาคม พ.ศ.
A5: ที่ | B5: ชื่อ -นามสกุล | C5: เพศ | D5: วัน เดือน ปี | E5: วัน เดือน ปี | F5: อายุ | I5: น้ำหนัก | J5: ส่วนสูง | K5: ค่า BMI | L5: ผลการประเมิน
D6: เกิด | E6: บันทึก | F6: ปี | G6: เดือน | H6: วัน | I6: (ก.ก) | J6: (ซม.) | L6: น้ำหนัก | M6: ส่วนสูง
A7: 1 | B7: ='ข้อมูล'!C5 -> ด.ช. ห้องเรียน วิชาการ | C7: ='ข้อมูล'!D5 -> ชาย | D7: ='ข้อมูล'!E5 -> 39818 | E7: 45071 | F7: =DATEDIF(D7,E7,"y") -> 14 | G7: =DATEDIF(D7,E7,"ym") -> 4 | H7: =DATEDIF(D7,E7,"md") -> 20 | I7: 47 | J7: 159 | K7: =IF(B7="","",I7/((J7/100)^2)) -> 18.591037 | L7: =IF($B7="","",IF($C7="ชาย",IF(K7<=VLOOKUP(F7,'เกณฑ์ดัชนีมวลกาย'!A5:U19,3,FALSE),"ผอมมาก",IF(K7<=VLOOKUP(F7,'เกณฑ์ดัชนีมวลกาย'!A5:U19,5,FALSE),"ผอม",IF(K7<=VLOOKUP(F7,'เกณฑ์ดัชนีมวลกาย'!A5:U19,7,FALSE),"สมส่วน",IF(K7<=VLOOKUP(F7,'เกณฑ์ดัชนีมวลกาย'!A5:U19,9,FALSE),"ท้วม","อ้วน")))),IF(K7<=VLOOKUP(F7,'เกณฑ์ดัชนีมวลกาย'!A5:U19,13,FALSE),"ผอมมาก",IF(K7<=VLOOKUP(F7,'เกณฑ์ดัชนีมวลกาย'!A5:U19,15,FALSE),"ผอม",IF(K7<=VLOOKUP(F7,'เกณฑ์ดัชนีมวลกาย'!A5:U19,17,FALSE),"สมส่วน",IF(K7<=VLOOKUP(F7,'เกณฑ์ดัชนีมวลกาย'!A5:U19,19,FALSE),"ท้วม","อ้วน")))))) -> สมส่วน | M7: =IF($B7="","",IF($C7="ชาย",IF(J7<=VLOOKUP(F7,'เกณฑ์ส่วนสูง'!A5:U19,3,FALSE),"เตี้ย",IF(J7<=VLOOKUP(F7,'เกณฑ์ส่วนสูง'!A5:U19,5,FALSE),"ค่อนข้างเตี้ย",IF(J7<=VLOOKUP(F7,'เกณฑ์ส่วนสูง'!A5:U19,7,FALSE),"ส่วนสูงตามเกณฑ์",IF(J7<=VLOOKUP(F7,'เกณฑ์ส่วนสูง'!A5:U19,9,FALSE),"ค่อนข้างสูง","สูง")))),IF(J7<=VLOOKUP(F7,'เกณฑ์ส่วนสูง'!A5:U19,13,FALSE),"เตี้ย",IF(J7<=VLOOKUP(F7,'เกณฑ์ส่วนสูง'!A5:U19,15,FALSE),"ค่อนข้างเตี้ย",IF(J7<=VLOOKUP(F7,'เกณฑ์ส่วนสูง'!A5:U19,17,FALSE),"ส่วนสูงตามเกณฑ์",IF(J7<=VLOOKUP(F7,'เกณฑ์ส่วนสูง'!A5:U19,19,FALSE),"ค่อนข้างสูง","สูง")))))) -> ส่วนสูงตามเกณฑ์
A8: 2 | B8: ='ข้อมูล'!C6 -> ด.ช. ห้องเรียน วิชาการ | C8: ='ข้อมูล'!D6 -> ชาย | D8: ='ข้อมูล'!E6 -> 39942 | E8: 45071 | F8: =DATEDIF(D8,E8,"y") -> 14 | G8: =DATEDIF(D8,E8,"ym") -> 0 | H8: =DATEDIF(D8,E8,"md") -> 16 | I8: 42 | J8: 155 | K8: =IF(B8="","",I8/((J8/100)^2)) -> 17.48179 | L8: =IF($B8="","",IF($C8="ชาย",IF(K8<=VLOOKUP(F8,'เกณฑ์ดัชนีมวลกาย'!A5:U19,3,FALSE),"ผอมมาก",IF(K8<=VLOOKUP(F8,'เกณฑ์ดัชนีมวลกาย'!A5:U19,5,FALSE),"ผอม",IF(K8<=VLOOKUP(F8,'เกณฑ์ดัชนีมวลกาย'!A5:U19,7,FALSE),"สมส่วน",IF(K8<=VLOOKUP(F8,'เกณฑ์ดัชนีมวลกาย'!A5:U19,9,FALSE),"ท้วม","อ้วน")))),IF(K8<=VLOOKUP(F8,'เกณฑ์ดัชนีมวลกาย'!A5:U19,13,FALSE),"ผอมมาก",IF(K8<=VLOOKUP(F8,'เกณฑ์ดัชนีมวลกาย'!A5:U19,15,FALSE),"ผอม",IF(K8<=VLOOKUP(F8,'เกณฑ์ดัชนีมวลกาย'!A5:U19,17,FALSE),"สมส่วน",IF(K8<=VLOOKUP(F8,'เกณฑ์ดัชนีมวลกาย'!A5:U19,19,FALSE),"ท้วม","อ้วน")))))) -> ผอม | M8: =IF($B8="","",IF($C8="ชาย",IF(J8<=VLOOKUP(F8,'เกณฑ์ส่วนสูง'!A5:U19,3,FALSE),"เตี้ย",IF(J8<=VLOOKUP(F8,'เกณฑ์ส่วนสูง'!A5:U19,5,FALSE),"ค่อนข้างเตี้ย",IF(J8<=VLOOKUP(F8,'เกณฑ์ส่วนสูง'!A5:U19,7,FALSE),"ส่วนสูงตามเกณฑ์",IF(J8<=VLOOKUP(F8,'เกณฑ์ส่วนสูง'!A5:U19,9,FALSE),"ค่อนข้างสูง","สูง")))),IF(J8<=VLOOKUP(F8,'เกณฑ์ส่วนสูง'!A5:U19,13,FALSE),"เตี้ย",IF(J8<=VLOOKUP(F8,'เกณฑ์ส่วนสูง'!A5:U19,15,FALSE),"ค่อนข้างเตี้ย",IF(J8<=VLOOKUP(F8,'เกณฑ์ส่วนสูง'!A5:U19,17,FALSE),"ส่วนสูงตามเกณฑ์",IF(J8<=VLOOKUP(F8,'เกณฑ์ส่วนสูง'!A5:U19,19,FALSE),"ค่อนข้างสูง","สูง")))))) -> ส่วนสูงตามเกณฑ์
A9: 3 | B9: ='ข้อมูล'!C7 -> ด.ช. ห้องเรียน วิชาการ | C9: ='ข้อมูล'!D7 -> ชาย | D9: ='ข้อมูล'!E7 -> 39475 | E9: 45071 | F9: =DATEDIF(D9,E9,"y") -> 15 | G9: =DATEDIF(D9,E9,"ym") -> 3 | H9: =DATEDIF(D9,E9,"md") -> 27 | I9: 58 | J9: 173 | K9: =IF(B9="","",I9/((J9/100)^2)) -> 19.379197 | L9: =IF($B9="","",IF($C9="ชาย",IF(K9<=VLOOKUP(F9,'เกณฑ์ดัชนีมวลกาย'!A5:U19,3,FALSE),"ผอมมาก",IF(K9<=VLOOKUP(F9,'เกณฑ์ดัชนีมวลกาย'!A5:U19,5,FALSE),"ผอม",IF(K9<=VLOOKUP(F9,'เกณฑ์ดัชนีมวลกาย'!A5:U19,7,FALSE),"สมส่วน",IF(K9<=VLOOKUP(F9,'เกณฑ์ดัชนีมวลกาย'!A5:U19,9,FALSE),"ท้วม","อ้วน")))),IF(K9<=VLOOKUP(F9,'เกณฑ์ดัชนีมวลกาย'!A5:U19,13,FALSE),"ผอมมาก",IF(K9<=VLOOKUP(F9,'เกณฑ์ดัชนีมวลกาย'!A5:U19,15,FALSE),"ผอม",IF(K9<=VLOOKUP(F9,'เกณฑ์ดัชนีมวลกาย'!A5:U19,17,FALSE),"สมส่วน",IF(K9<=VLOOKUP(F9,'เกณฑ์ดัชนีมวลกาย'!A5:U19,19,FALSE),"ท้วม","อ้วน")))))) -> สมส่วน | M9: =IF($B9="","",IF($C9="ชาย",IF(J9<=VLOOKUP(F9,'เกณฑ์ส่วนสูง'!A5:U19,3,FALSE),"เตี้ย",IF(J9<=VLOOKUP(F9,'เกณฑ์ส่วนสูง'!A5:U19,5,FALSE),"ค่อนข้างเตี้ย",IF(J9<=VLOOKUP(F9,'เกณฑ์ส่วนสูง'!A5:U19,7,FALSE),"ส่วนสูงตามเกณฑ์",IF(J9<=VLOOKUP(F9,'เกณฑ์ส่วนสูง'!A5:U19,9,FALSE),"ค่อนข้างสูง","สูง")))),IF(J9<=VLOOKUP(F9,'เกณฑ์ส่วนสูง'!A5:U19,13,FALSE),"เตี้ย",IF(J9<=VLOOKUP(F9,'เกณฑ์ส่วนสูง'!A5:U19,15,FALSE),"ค่อนข้างเตี้ย",IF(J9<=VLOOKUP(F9,'เกณฑ์ส่วนสูง'!A5:U19,17,FALSE),"ส่วนสูงตามเกณฑ์",IF(J9<=VLOOKUP(F9,'เกณฑ์ส่วนสูง'!A5:U19,19,FALSE),"ค่อนข้างสูง","สูง")))))) -> ส่วนสูงตามเกณฑ์
A10: 4 | B10: ='ข้อมูล'!C8 -> ด.ช. ห้องเรียน วิชาการ | C10: ='ข้อมูล'!D8 -> ชาย | D10: ='ข้อมูล'!E8 -> 39895 | E10: 45071 | F10: =DATEDIF(D10,E10,"y") -> 14 | G10: =DATEDIF(D10,E10,"ym") -> 2 | H10: =DATEDIF(D10,E10,"md") -> 2 | I10: 46.6 | J10: 162 | K10: =IF(B10="","",I10/((J10/100)^2)) -> 17.75644 | L10: =IF($B10="","",IF($C10="ชาย",IF(K10<=VLOOKUP(F10,'เกณฑ์ดัชนีมวลกาย'!A5:U19,3,FALSE),"ผอมมาก",IF(K10<=VLOOKUP(F10,'เกณฑ์ดัชนีมวลกาย'!A5:U19,5,FALSE),"ผอม",IF(K10<=VLOOKUP(F10,'เกณฑ์ดัชนีมวลกาย'!A5:U19,7,FALSE),"สมส่วน",IF(K10<=VLOOKUP(F10,'เกณฑ์ดัชนีมวลกาย'!A5:U19,9,FALSE),"ท้วม","อ้วน")))),IF(K10<=VLOOKUP(F10,'เกณฑ์ดัชนีมวลกาย'!A5:U19,13,FALSE),"ผอมมาก",IF(K10<=VLOOKUP(F10,'เกณฑ์ดัชนีมวลกาย'!A5:U19,15,FALSE),"ผอม",IF(K10<=VLOOKUP(F10,'เกณฑ์ดัชนีมวลกาย'!A5:U19,17,FALSE),"สมส่วน",IF(K10<=VLOOKUP(F10,'เกณฑ์ดัชนีมวลกาย'!A5:U19,19,FALSE),"ท้วม","อ้วน")))))) -> สมส่วน | M10: =IF($B10="","",IF($C10="ชาย",IF(J10<=VLOOKUP(F10,'เกณฑ์ส่วนสูง'!A5:U19,3,FALSE),"เตี้ย",IF(J10<=VLOOKUP(F10,'เกณฑ์ส่วนสูง'!A5:U19,5,FALSE),"ค่อนข้างเตี้ย",IF(J10<=VLOOKUP(F10,'เกณฑ์ส่วนสูง'!A5:U19,7,FALSE),"ส่วนสูงตามเกณฑ์",IF(J10<=VLOOKUP(F10,'เกณฑ์ส่วนสูง'!A5:U19,9,FALSE),"ค่อนข้างสูง","สูง")))),IF(J10<=VLOOKUP(F10,'เกณฑ์ส่วนสูง'!A5:U19,13,FALSE),"เตี้ย",IF(J10<=VLOOKUP(F10,'เกณฑ์ส่วนสูง'!A5:U19,15,FALSE),"ค่อนข้างเตี้ย",IF(J10<=VLOOKUP(F10,'เกณฑ์ส่วนสูง'!A5:U19,17,FALSE),"ส่วนสูงตามเกณฑ์",IF(J10<=VLOOKUP(F10,'เกณฑ์ส่วนสูง'!A5:U19,19,FALSE),"ค่อนข้างสูง","สูง")))))) -> ส่วนสูงตามเกณฑ์
A11: 5 | B11: ='ข้อมูล'!C9 -> ด.ช. ห้องเรียน วิชาการ | C11: ='ข้อมูล'!D9 -> ชาย | D11: ='ข้อมูล'!E9 -> 39880 | E11: 45071 | F11: =DATEDIF(D11,E11,"y") -> 14 | G11: =DATEDIF(D11,E11,"ym") -> 2 | H11: =DATEDIF(D11,E11,"md") -> 17 | I11: 46.6 | J11: 162 | K11: =IF(B11="","",I11/((J11/100)^2)) -> 17.75644 | L11: =IF($B11="","",IF($C11="ชาย",IF(K11<=VLOOKUP(F11,'เกณฑ์ดัชนีมวลกาย'!A5:U19,3,FALSE),"ผอมมาก",IF(K11<=VLOOKUP(F11,'เกณฑ์ดัชนีมวลกาย'!A5:U19,5,FALSE),"ผอม",IF(K11<=VLOOKUP(F11,'เกณฑ์ดัชนีมวลกาย'!A5:U19,7,FALSE),"สมส่วน",IF(K11<=VLOOKUP(F11,'เกณฑ์ดัชนีมวลกาย'!A5:U19,9,FALSE),"ท้วม","อ้วน")))),IF(K11<=VLOOKUP(F11,'เกณฑ์ดัชนีมวลกาย'!A5:U19,13,FALSE),"ผอมมาก",IF(K11<=VLOOKUP(F11,'เกณฑ์ดัชนีมวลกาย'!A5:U19,15,FALSE),"ผอม",IF(K11<=VLOOKUP(F11,'เกณฑ์ดัชนีมวลกาย'!A5:U19,17,FALSE),"สมส่วน",IF(K11<=VLOOKUP(F11,'เกณฑ์ดัชนีมวลกาย'!A5:U19,19,FALSE),"ท้วม","อ้วน")))))) -> สมส่วน | M11: =IF($B11="","",IF($C11="ชาย",IF(J11<=VLOOKUP(F11,'เกณฑ์ส่วนสูง'!A5:U19,3,FALSE),"เตี้ย",IF(J11<=VLOOKUP(F11,'เกณฑ์ส่วนสูง'!A5:U19,5,FALSE),"ค่อนข้างเตี้ย",IF(J11<=VLOOKUP(F11,'เกณฑ์ส่วนสูง'!A5:U19,7,FALSE),"ส่วนสูงตามเกณฑ์",IF(J11<=VLOOKUP(F11,'เกณฑ์ส่วนสูง'!A5:U19,9,FALSE),"ค่อนข้างสูง","สูง")))),IF(J11<=VLOOKUP(F11,'เกณฑ์ส่วนสูง'!A5:U19,13,FALSE),"เตี้ย",IF(J11<=VLOOKUP(F11,'เกณฑ์ส่วนสูง'!A5:U19,15,FALSE),"ค่อนข้างเตี้ย",IF(J11<=VLOOKUP(F11,'เกณฑ์ส่วนสูง'!A5:U19,17,FALSE),"ส่วนสูงตามเกณฑ์",IF(J11<=VLOOKUP(F11,'เกณฑ์ส่วนสูง'!A5:U19,19,FALSE),"ค่อนข้างสูง","สูง")))))) -> ส่วนสูงตามเกณฑ์
A12: 6 | B12: ='ข้อมูล'!C10 -> ด.ช. ห้องเรียน วิชาการ | C12: ='ข้อมูล'!D10 -> ชาย | D12: ='ข้อมูล'!E10 -> 39735 | E12: 45071 | F12: =DATEDIF(D12,E12,"y") -> 14 | G12: =DATEDIF(D12,E12,"ym") -> 7 | H12: =DATEDIF(D12,E12,"md") -> 11 | I12: 40.8 | J12: 160 | K12: =IF(B12="","",I12/((J12/100)^2)) -> 15.9375 | L12: =IF($B12="","",IF($C12="ชาย",IF(K12<=VLOOKUP(F12,'เกณฑ์ดัชนีมวลกาย'!A5:U19,3,FALSE),"ผอมมาก",IF(K12<=VLOOKUP(F12,'เกณฑ์ดัชนีมวลกาย'!A5:U19,5,FALSE),"ผอม",IF(K12<=VLOOKUP(F12,'เกณฑ์ดัชนีมวลกาย'!A5:U19,7,FALSE),"สมส่วน",IF(K12<=VLOOKUP(F12,'เกณฑ์ดัชนีมวลกาย'!A5:U19,9,FALSE),"ท้วม","อ้วน")))),IF(K12<=VLOOKUP(F12,'เกณฑ์ดัชนีมวลกาย'!A5:U19,13,FALSE),"ผอมมาก",IF(K12<=VLOOKUP(F12,'เกณฑ์ดัชนีมวลกาย'!A5:U19,15,FALSE),"ผอม",IF(K12<=VLOOKUP(F12,'เกณฑ์ดัชนีมวลกาย'!A5:U19,17,FALSE),"สมส่วน",IF(K12<=VLOOKUP(F12,'เกณฑ์ดัชนีมวลกาย'!A5:U19,19,FALSE),"ท้วม","อ้วน")))))) -> ผอม | M12: =IF($B12="","",IF($C12="ชาย",IF(J12<=VLOOKUP(F12,'เกณฑ์ส่วนสูง'!A5:U19,3,FALSE),"เตี้ย",IF(J12<=VLOOKUP(F12,'เกณฑ์ส่วนสูง'!A5:U19,5,FALSE),"ค่อนข้างเตี้ย",IF(J12<=VLOOKUP(F12,'เกณฑ์ส่วนสูง'!A5:U19,7,FALSE),"ส่วนสูงตามเกณฑ์",IF(J12<=VLOOKUP(F12,'เกณฑ์ส่วนสูง'!A5:U19,9,FALSE),"ค่อนข้างสูง","สูง")))),IF(J12<=VLOOKUP(F12,'เกณฑ์ส่วนสูง'!A5:U19,13,FALSE),"เตี้ย",IF(J12<=VLOOKUP(F12,'เกณฑ์ส่วนสูง'!A5:U19,15,FALSE),"ค่อนข้างเตี้ย",IF(J12<=VLOOKUP(F12,'เกณฑ์ส่วนสูง'!A5:U19,17,FALSE),"ส่วนสูงตามเกณฑ์",IF(J12<=VLOOKUP(F12,'เกณฑ์ส่วนสูง'!A5:U19,19,FALSE),"ค่อนข้างสูง","สูง")))))) -> ส่วนสูงตามเกณฑ์
A13: 7 | B13: ='ข้อมูล'!C11 -> ด.ช. ห้องเรียน วิชาการ | C13: ='ข้อมูล'!D11 -> ชาย | D13: ='ข้อมูล'!E11 -> 39767 | E13: 45066 | F13: =DATEDIF(D13,E13,"y") -> 14 | G13: =DATEDIF(D13,E13,"ym") -> 6 | H13: =DATEDIF(D13,E13,"md") -> 5 | I13: 73.4 | J13: 154 | K13: =IF(B13="","",I13/((J13/100)^2)) -> 30.94957 | L13: =IF($B13="","",IF($C13="ชาย",IF(K13<=VLOOKUP(F13,'เกณฑ์ดัชนีมวลกาย'!A5:U19,3,FALSE),"ผอมมาก",IF(K13<=VLOOKUP(F13,'เกณฑ์ดัชนีมวลกาย'!A5:U19,5,FALSE),"ผอม",IF(K13<=VLOOKUP(F13,'เกณฑ์ดัชนีมวลกาย'!A5:U19,7,FALSE),"สมส่วน",IF(K13<=VLOOKUP(F13,'เกณฑ์ดัชนีมวลกาย'!A5:U19,9,FALSE),"ท้วม","อ้วน")))),IF(K13<=VLOOKUP(F13,'เกณฑ์ดัชนีมวลกาย'!A5:U19,13,FALSE),"ผอมมาก",IF(K13<=VLOOKUP(F13,'เกณฑ์ดัชนีมวลกาย'!A5:U19,15,FALSE),"ผอม",IF(K13<=VLOOKUP(F13,'เกณฑ์ดัชนีมวลกาย'!A5:U19,17,FALSE),"สมส่วน",IF(K13<=VLOOKUP(F13,'เกณฑ์ดัชนีมวลกาย'!A5:U19,19,FALSE),"ท้วม","อ้วน")))))) -> อ้วน | M13: =IF($B13="","",IF($C13="ชาย",IF(J13<=VLOOKUP(F13,'เกณฑ์ส่วนสูง'!A5:U19,3,FALSE),"เตี้ย",IF(J13<=VLOOKUP(F13,'เกณฑ์ส่วนสูง'!A5:U19,5,FALSE),"ค่อนข้างเตี้ย",IF(J13<=VLOOKUP(F13,'เกณฑ์ส่วนสูง'!A5:U19,7,FALSE),"ส่วนสูงตามเกณฑ์",IF(J13<=VLOOKUP(F13,'เกณฑ์ส่วนสูง'!A5:U19,9,FALSE),"ค่อนข้างสูง","สูง")))),IF(J13<=VLOOKUP(F13,'เกณฑ์ส่วนสูง'!A5:U19,13,FALSE),"เตี้ย",IF(J13<=VLOOKUP(F13,'เกณฑ์ส่วนสูง'!A5:U19,15,FALSE),"ค่อนข้างเตี้ย",IF(J13<=VLOOKUP(F13,'เกณฑ์ส่วนสูง'!A5:U19,17,FALSE),"ส่วนสูงตามเกณฑ์",IF(J13<=VLOOKUP(F13,'เกณฑ์ส่วนสูง'!A5:U19,19,FALSE),"ค่อนข้างสูง","สูง")))))) -> ส่วนสูงตามเกณฑ์
A14: 8 | B14: ='ข้อมูล'!C12 -> ด.ช. ห้องเรียน วิชาการ | C14: ='ข้อมูล'!D12 -> ชาย | D14: ='ข้อมูล'!E12 -> 39612 | E14: 45066 | F14: =DATEDIF(D14,E14,"y") -> 14 | G14: =DATEDIF(D14,E14,"ym") -> 11 | H14: =DATEDIF(D14,E14,"md") -> 7 | I14: 90 | J14: 177 | K14: =IF(B14="","",I14/((J14/100)^2)) -> 28.727377 | L14: =IF($B14="","",IF($C14="ชาย",IF(K14<=VLOOKUP(F14,'เกณฑ์ดัชนีมวลกาย'!A5:U19,3,FALSE),"ผอมมาก",IF(K14<=VLOOKUP(F14,'เกณฑ์ดัชนีมวลกาย'!A5:U19,5,FALSE),"ผอม",IF(K14<=VLOOKUP(F14,'เกณฑ์ดัชนีมวลกาย'!A5:U19,7,FALSE),"สมส่วน",IF(K14<=VLOOKUP(F14,'เกณฑ์ดัชนีมวลกาย'!A5:U19,9,FALSE),"ท้วม","อ้วน")))),IF(K14<=VLOOKUP(F14,'เกณฑ์ดัชนีมวลกาย'!A5:U19,13,FALSE),"ผอมมาก",IF(K14<=VLOOKUP(F14,'เกณฑ์ดัชนีมวลกาย'!A5:U19,15,FALSE),"ผอม",IF(K14<=VLOOKUP(F14,'เกณฑ์ดัชนีมวลกาย'!A5:U19,17,FALSE),"สมส่วน",IF(K14<=VLOOKUP(F14,'เกณฑ์ดัชนีมวลกาย'!A5:U19,19,FALSE),"ท้วม","อ้วน")))))) -> อ้วน | M14: =IF($B14="","",IF($C14="ชาย",IF(J14<=VLOOKUP(F14,'เกณฑ์ส่วนสูง'!A5:U19,3,FALSE),"เตี้ย",IF(J14<=VLOOKUP(F14,'เกณฑ์ส่วนสูง'!A5:U19,5,FALSE),"ค่อนข้างเตี้ย",IF(J14<=VLOOKUP(F14,'เกณฑ์ส่วนสูง'!A5:U19,7,FALSE),"ส่วนสูงตามเกณฑ์",IF(J14<=VLOOKUP(F14,'เกณฑ์ส่วนสูง'!A5:U19,9,FALSE),"ค่อนข้างสูง","สูง")))),IF(J14<=VLOOKUP(F14,'เกณฑ์ส่วนสูง'!A5:U19,13,FALSE),"เตี้ย",IF(J14<=VLOOKUP(F14,'เกณฑ์ส่วนสูง'!A5:U19,15,FALSE),"ค่อนข้างเตี้ย",IF(J14<=VLOOKUP(F14,'เกณฑ์ส่วนสูง'!A5:U19,17,FALSE),"ส่วนสูงตามเกณฑ์",IF(J14<=VLOOKUP(F14,'เกณฑ์ส่วนสูง'!A5:U19,19,FALSE),"ค่อนข้างสูง","สูง")))))) -> สูง
A15: 9 | B15: ='ข้อมูล'!C13 -> ด.ช. ห้องเรียน วิชาการ | C15: ='ข้อมูล'!D13 -> ชาย | D15: ='ข้อมูล'!E13 -> 39930 | E15: 45066 | F15: =DATEDIF(D15,E15,"y") -> 14 | G15: =DATEDIF(D15,E15,"ym") -> 0 | H15: =DATEDIF(D15,E15,"md") -> 23 | I15: 41 | J15: 152 | K15: =IF(B15="","",I15/((J15/100)^2)) -> 17.745845 | L15: =IF($B15="","",IF($C15="ชาย",IF(K15<=VLOOKUP(F15,'เกณฑ์ดัชนีมวลกาย'!A5:U19,3,FALSE),"ผอมมาก",IF(K15<=VLOOKUP(F15,'เกณฑ์ดัชนีมวลกาย'!A5:U19,5,FALSE),"ผอม",IF(K15<=VLOOKUP(F15,'เกณฑ์ดัชนีมวลกาย'!A5:U19,7,FALSE),"สมส่วน",IF(K15<=VLOOKUP(F15,'เกณฑ์ดัชนีมวลกาย'!A5:U19,9,FALSE),"ท้วม","อ้วน")))),IF(K15<=VLOOKUP(F15,'เกณฑ์ดัชนีมวลกาย'!A5:U19,13,FALSE),"ผอมมาก",IF(K15<=VLOOKUP(F15,'เกณฑ์ดัชนีมวลกาย'!A5:U19,15,FALSE),"ผอม",IF(K15<=VLOOKUP(F15,'เกณฑ์ดัชนีมวลกาย'!A5:U19,17,FALSE),"สมส่วน",IF(K15<=VLOOKUP(F15,'เกณฑ์ดัชนีมวลกาย'!A5:U19,19,FALSE),"ท้วม","อ้วน")))))) -> สมส่วน | M15: =IF($B15="","",IF($C15="ชาย",IF(J15<=VLOOKUP(F15,'เกณฑ์ส่วนสูง'!A5:U19,3,FALSE),"เตี้ย",IF(J15<=VLOOKUP(F15,'เกณฑ์ส่วนสูง'!A5:U19,5,FALSE),"ค่อนข้างเตี้ย",IF(J15<=VLOOKUP(F15,'เกณฑ์ส่วนสูง'!A5:U19,7,FALSE),"ส่วนสูงตามเกณฑ์",IF(J15<=VLOOKUP(F15,'เกณฑ์ส่วนสูง'!A5:U19,9,FALSE),"ค่อนข้างสูง","สูง")))),IF(J15<=VLOOKUP(F15,'เกณฑ์ส่วนสูง'!A5:U19,13,FALSE),"เตี้ย",IF(J15<=VLOOKUP(F15,'เกณฑ์ส่วนสูง'!A5:U19,15,FALSE),"ค่อนข้างเตี้ย",IF(J15<=VLOOKUP(F15,'เกณฑ์ส่วนสูง'!A5:U19,17,FALSE),"ส่วนสูงตามเกณฑ์",IF(J15<=VLOOKUP(F15,'เกณฑ์ส่วนสูง'!A5:U19,19,FALSE),"ค่อนข้างสูง","สูง")))))) -> ส่วนสูงตามเกณฑ์
A16: 10 | B16: ='ข้อมูล'!C14 -> ด.ญ.ห้องเรียน วิชาการ | C16: ='ข้อมูล'!D14 -> หญิง | D16: ='ข้อมูล'!E14 -> 39687 | E16: 45066 | F16: =DATEDIF(D16,E16,"y") -> 14 | G16: =DATEDIF(D16,E16,"ym") -> 8 | H16: =DATEDIF(D16,E16,"md") -> 23 | I16: 58 | J16: 155 | K16: =IF(B16="","",I16/((J16/100)^2)) -> 24.141519 | L16: =IF($B16="","",IF($C16="ชาย",IF(K16<=VLOOKUP(F16,'เกณฑ์ดัชนีมวลกาย'!A5:U19,3,FALSE),"ผอมมาก",IF(K16<=VLOOKUP(F16,'เกณฑ์ดัชนีมวลกาย'!A5:U19,5,FALSE),"ผอม",IF(K16<=VLOOKUP(F16,'เกณฑ์ดัชนีมวลกาย'!A5:U19,7,FALSE),"สมส่วน",IF(K16<=VLOOKUP(F16,'เกณฑ์ดัชนีมวลกาย'!A5:U19,9,FALSE),"ท้วม","อ้วน")))),IF(K16<=VLOOKUP(F16,'เกณฑ์ดัชนีมวลกาย'!A5:U19,13,FALSE),"ผอมมาก",IF(K16<=VLOOKUP(F16,'เกณฑ์ดัชนีมวลกาย'!A5:U19,15,FALSE),"ผอม",IF(K16<=VLOOKUP(F16,'เกณฑ์ดัชนีมวลกาย'!A5:U19,17,FALSE),"สมส่วน",IF(K16<=VLOOKUP(F16,'เกณฑ์ดัชนีมวลกาย'!A5:U19,19,FALSE),"ท้วม","อ้วน")))))) -> ท้วม | M16: =IF($B16="","",IF($C16="ชาย",IF(J16<=VLOOKUP(F16,'เกณฑ์ส่วนสูง'!A5:U19,3,FALSE),"เตี้ย",IF(J16<=VLOOKUP(F16,'เกณฑ์ส่วนสูง'!A5:U19,5,FALSE),"ค่อนข้างเตี้ย",IF(J16<=VLOOKUP(F16,'เกณฑ์ส่วนสูง'!A5:U19,7,FALSE),"ส่วนสูงตามเกณฑ์",IF(J16<=VLOOKUP(F16,'เกณฑ์ส่วนสูง'!A5:U19,9,FALSE),"ค่อนข้างสูง","สูง")))),IF(J16<=VLOOKUP(F16,'เกณฑ์ส่วนสูง'!A5:U19,13,FALSE),"เตี้ย",IF(J16<=VLOOKUP(F16,'เกณฑ์ส่วนสูง'!A5:U19,15,FALSE),"ค่อนข้างเตี้ย",IF(J16<=VLOOKUP(F16,'เกณฑ์ส่วนสูง'!A5:U19,17,FALSE),"ส่วนสูงตามเกณฑ์",IF(J16<=VLOOKUP(F16,'เกณฑ์ส่วนสูง'!A5:U19,19,FALSE),"ค่อนข้างสูง","สูง")))))) -> ส่วนสูงตามเกณฑ์
A17: 11 | B17: ='ข้อมูล'!C15 -> ด.ญ.ห้องเรียน วิชาการ | C17: ='ข้อมูล'!D15 -> หญิง | D17: ='ข้อมูล'!E15 -> 39234 | E17: 45066 | F17: =DATEDIF(D17,E17,"y") -> 15 | G17: =DATEDIF(D17,E17,"ym") -> 11 | H17: =DATEDIF(D17,E17,"md") -> 19 | I17: 48 | J17: 165 | K17: =IF(B17="","",I17/((J17/100)^2)) -> 17.630854 | L17: =IF($B17="","",IF($C17="ชาย",IF(K17<=VLOOKUP(F17,'เกณฑ์ดัชนีมวลกาย'!A5:U19,3,FALSE),"ผอมมาก",IF(K17<=VLOOKUP(F17,'เกณฑ์ดัชนีมวลกาย'!A5:U19,5,FALSE),"ผอม",IF(K17<=VLOOKUP(F17,'เกณฑ์ดัชนีมวลกาย'!A5:U19,7,FALSE),"สมส่วน",IF(K17<=VLOOKUP(F17,'เกณฑ์ดัชนีมวลกาย'!A5:U19,9,FALSE),"ท้วม","อ้วน")))),IF(K17<=VLOOKUP(F17,'เกณฑ์ดัชนีมวลกาย'!A5:U19,13,FALSE),"ผอมมาก",IF(K17<=VLOOKUP(F17,'เกณฑ์ดัชนีมวลกาย'!A5:U19,15,FALSE),"ผอม",IF(K17<=VLOOKUP(F17,'เกณฑ์ดัชนีมวลกาย'!A5:U19,17,FALSE),"สมส่วน",IF(K17<=VLOOKUP(F17,'เกณฑ์ดัชนีมวลกาย'!A5:U19,19,FALSE),"ท้วม","อ้วน")))))) -> ผอม | M17: =IF($B17="","",IF($C17="ชาย",IF(J17<=VLOOKUP(F17,'เกณฑ์ส่วนสูง'!A5:U19,3,FALSE),"เตี้ย",IF(J17<=VLOOKUP(F17,'เกณฑ์ส่วนสูง'!A5:U19,5,FALSE),"ค่อนข้างเตี้ย",IF(J17<=VLOOKUP(F17,'เกณฑ์ส่วนสูง'!A5:U19,7,FALSE),"ส่วนสูงตามเกณฑ์",IF(J17<=VLOOKUP(F17,'เกณฑ์ส่วนสูง'!A5:U19,9,FALSE),"ค่อนข้างสูง","สูง")))),IF(J17<=VLOOKUP(F17,'เกณฑ์ส่วนสูง'!A5:U19,13,FALSE),"เตี้ย",IF(J17<=VLOOKUP(F17,'เกณฑ์ส่วนสูง'!A5:U19,15,FALSE),"ค่อนข้างเตี้ย",IF(J17<=VLOOKUP(F17,'เกณฑ์ส่วนสูง'!A5:U19,17,FALSE),"ส่วนสูงตามเกณฑ์",IF(J17<=VLOOKUP(F17,'เกณฑ์ส่วนสูง'!A5:U19,19,FALSE),"ค่อนข้างสูง","สูง")))))) -> ค่อนข้างสูง
A18: 12 | B18: ='ข้อมูล'!C16 -> ด.ญ.ห้องเรียน วิชาการ | C18: ='ข้อมูล'!D16 -> หญิง | D18: ='ข้อมูล'!E16 -> 38997 | E18: 45071 | F18: =DATEDIF(D18,E18,"y") -> 16 | G18: =DATEDIF(D18,E18,"ym") -> 7 | H18: =DATEDIF(D18,E18,"md") -> 18 | I18: 65 | J18: 167 | K18: =IF(B18="","",I18/((J18/100)^2)) -> 23.30668 | L18: =IF($B18="","",IF($C18="ชาย",IF(K18<=VLOOKUP(F18,'เกณฑ์ดัชนีมวลกาย'!A5:U19,3,FALSE),"ผอมมาก",IF(K18<=VLOOKUP(F18,'เกณฑ์ดัชนีมวลกาย'!A5:U19,5,FALSE),"ผอม",IF(K18<=VLOOKUP(F18,'เกณฑ์ดัชนีมวลกาย'!A5:U19,7,FALSE),"สมส่วน",IF(K18<=VLOOKUP(F18,'เกณฑ์ดัชนีมวลกาย'!A5:U19,9,FALSE),"ท้วม","อ้วน")))),IF(K18<=VLOOKUP(F18,'เกณฑ์ดัชนีมวลกาย'!A5:U19,13,FALSE),"ผอมมาก",IF(K18<=VLOOKUP(F18,'เกณฑ์ดัชนีมวลกาย'!A5:U19,15,FALSE),"ผอม",IF(K18<=VLOOKUP(F18,'เกณฑ์ดัชนีมวลกาย'!A5:U19,17,FALSE),"สมส่วน",IF(K18<=VLOOKUP(F18,'เกณฑ์ดัชนีมวลกาย'!A5:U19,19,FALSE),"ท้วม","อ้วน")))))) -> สมส่วน | M18: =IF($B18="","",IF($C18="ชาย",IF(J18<=VLOOKUP(F18,'เกณฑ์ส่วนสูง'!A5:U19,3,FALSE),"เตี้ย",IF(J18<=VLOOKUP(F18,'เกณฑ์ส่วนสูง'!A5:U19,5,FALSE),"ค่อนข้างเตี้ย",IF(J18<=VLOOKUP(F18,'เกณฑ์ส่วนสูง'!A5:U19,7,FALSE),"ส่วนสูงตามเกณฑ์",IF(J18<=VLOOKUP(F18,'เกณฑ์ส่วนสูง'!A5:U19,9,FALSE),"ค่อนข้างสูง","สูง")))),IF(J18<=VLOOKUP(F18,'เกณฑ์ส่วนสูง'!A5:U19,13,FALSE),"เตี้ย",IF(J18<=VLOOKUP(F18,'เกณฑ์ส่วนสูง'!A5:U19,15,FALSE),"ค่อนข้างเตี้ย",IF(J18<=VLOOKUP(F18,'เกณฑ์ส่วนสูง'!A5:U19,17,FALSE),"ส่วนสูงตามเกณฑ์",IF(J18<=VLOOKUP(F18,'เกณฑ์ส่วนสูง'!A5:U19,19,FALSE),"ค่อนข้างสูง","สูง")))))) -> สูง
A19: 13 | B19: ='ข้อมูล'!C17 -> ด.ญ.ห้องเรียน วิชาการ | C19: ='ข้อมูล'!D17 -> หญิง | D19: ='ข้อมูล'!E17 -> 39553 | E19: 45071 | F19: =DATEDIF(D19,E19,"y") -> 15 | G19: =DATEDIF(D19,E19,"ym") -> 1 | H19: =DATEDIF(D19,E19,"md") -> 10 | I19: 58 | J19: 167 | K19: =IF(B19="","",I19/((J19/100)^2)) -> 20.79673 | L19: =IF($B19="","",IF($C19="ชาย",IF(K19<=VLOOKUP(F19,'เกณฑ์ดัชนีมวลกาย'!A5:U19,3,FALSE),"ผอมมาก",IF(K19<=VLOOKUP(F19,'เกณฑ์ดัชนีมวลกาย'!A5:U19,5,FALSE),"ผอม",IF(K19<=VLOOKUP(F19,'เกณฑ์ดัชนีมวลกาย'!A5:U19,7,FALSE),"สมส่วน",IF(K19<=VLOOKUP(F19,'เกณฑ์ดัชนีมวลกาย'!A5:U19,9,FALSE),"ท้วม","อ้วน")))),IF(K19<=VLOOKUP(F19,'เกณฑ์ดัชนีมวลกาย'!A5:U19,13,FALSE),"ผอมมาก",IF(K19<=VLOOKUP(F19,'เกณฑ์ดัชนีมวลกาย'!A5:U19,15,FALSE),"ผอม",IF(K19<=VLOOKUP(F19,'เกณฑ์ดัชนีมวลกาย'!A5:U19,17,FALSE),"สมส่วน",IF(K19<=VLOOKUP(F19,'เกณฑ์ดัชนีมวลกาย'!A5:U19,19,FALSE),"ท้วม","อ้วน")))))) -> สมส่วน | M19: =IF($B19="","",IF($C19="ชาย",IF(J19<=VLOOKUP(F19,'เกณฑ์ส่วนสูง'!A5:U19,3,FALSE),"เตี้ย",IF(J19<=VLOOKUP(F19,'เกณฑ์ส่วนสูง'!A5:U19,5,FALSE),"ค่อนข้างเตี้ย",IF(J19<=VLOOKUP(F19,'เกณฑ์ส่วนสูง'!A5:U19,7,FALSE),"ส่วนสูงตามเกณฑ์",IF(J19<=VLOOKUP(F19,'เกณฑ์ส่วนสูง'!A5:U19,9,FALSE),"ค่อนข้างสูง","สูง")))),IF(J19<=VLOOKUP(F19,'เกณฑ์ส่วนสูง'!A5:U19,13,FALSE),"เตี้ย",IF(J19<=VLOOKUP(F19,'เกณฑ์ส่วนสูง'!A5:U19,15,FALSE),"ค่อนข้างเตี้ย",IF(J19<=VLOOKUP(F19,'เกณฑ์ส่วนสูง'!A5:U19,17,FALSE),"ส่วนสูงตามเกณฑ์",IF(J19<=VLOOKUP(F19,'เกณฑ์ส่วนสูง'!A5:U19,19,FALSE),"ค่อนข้างสูง","สูง")))))) -> สูง
A20: 14 | B20: ='ข้อมูล'!C18 -> ด.ญ.ห้องเรียน วิชาการ | C20: ='ข้อมูล'!D18 -> หญิง | D20: ='ข้อมูล'!E18 -> 39860 | E20: 45071 | F20: =DATEDIF(D20,E20,"y") -> 14 | G20: =DATEDIF(D20,E20,"ym") -> 3 | H20: =DATEDIF(D20,E20,"md") -> 9 | I20: 46 | J20: 159 | K20: =IF(B20="","",I20/((J20/100)^2)) -> 18.195483 | L20: =IF($B20="","",IF($C20="ชาย",IF(K20<=VLOOKUP(F20,'เกณฑ์ดัชนีมวลกาย'!A5:U19,3,FALSE),"ผอมมาก",IF(K20<=VLOOKUP(F20,'เกณฑ์ดัชนีมวลกาย'!A5:U19,5,FALSE),"ผอม",IF(K20<=VLOOKUP(F20,'เกณฑ์ดัชนีมวลกาย'!A5:U19,7,FALSE),"สมส่วน",IF(K20<=VLOOKUP(F20,'เกณฑ์ดัชนีมวลกาย'!A5:U19,9,FALSE),"ท้วม","อ้วน")))),IF(K20<=VLOOKUP(F20,'เกณฑ์ดัชนีมวลกาย'!A5:U19,13,FALSE),"ผอมมาก",IF(K20<=VLOOKUP(F20,'เกณฑ์ดัชนีมวลกาย'!A5:U19,15,FALSE),"ผอม",IF(K20<=VLOOKUP(F20,'เกณฑ์ดัชนีมวลกาย'!A5:U19,17,FALSE),"สมส่วน",IF(K20<=VLOOKUP(F20,'เกณฑ์ดัชนีมวลกาย'!A5:U19,19,FALSE),"ท้วม","อ้วน")))))) -> สมส่วน | M20: =IF($B20="","",IF($C20="ชาย",IF(J20<=VLOOKUP(F20,'เกณฑ์ส่วนสูง'!A5:U19,3,FALSE),"เตี้ย",IF(J20<=VLOOKUP(F20,'เกณฑ์ส่วนสูง'!A5:U19,5,FALSE),"ค่อนข้างเตี้ย",IF(J20<=VLOOKUP(F20,'เกณฑ์ส่วนสูง'!A5:U19,7,FALSE),"ส่วนสูงตามเกณฑ์",IF(J20<=VLOOKUP(F20,'เกณฑ์ส่วนสูง'!A5:U19,9,FALSE),"ค่อนข้างสูง","สูง")))),IF(J20<=VLOOKUP(F20,'เกณฑ์ส่วนสูง'!A5:U19,13,FALSE),"เตี้ย",IF(J20<=VLOOKUP(F20,'เกณฑ์ส่วนสูง'!A5:U19,15,FALSE),"ค่อนข้างเตี้ย",IF(J20<=VLOOKUP(F20,'เกณฑ์ส่วนสูง'!A5:U19,17,FALSE),"ส่วนสูงตามเกณฑ์",IF(J20<=VLOOKUP(F20,'เกณฑ์ส่วนสูง'!A5:U19,19,FALSE),"ค่อนข้างสูง","สูง")))))) -> ส่วนสูงตามเกณฑ์
A21: 15 | B21: ='ข้อมูล'!C19 -> ด.ญ.ห้องเรียน วิชาการ | C21: ='ข้อมูล'!D19 -> หญิง | D21: ='ข้อมูล'!E19 -> 39861 | E21: 45071 | F21: =DATEDIF(D21,E21,"y") -> 14 | G21: =DATEDIF(D21,E21,"ym") -> 3 | H21: =DATEDIF(D21,E21,"md") -> 8 | I21: 46 | J21: 159 | K21: =IF(B21="","",I21/((J21/100)^2)) -> 18.195483 | L21: =IF($B21="","",IF($C21="ชาย",IF(K21<=VLOOKUP(F21,'เกณฑ์ดัชนีมวลกาย'!A5:U19,3,FALSE),"ผอมมาก",IF(K21<=VLOOKUP(F21,'เกณฑ์ดัชนีมวลกาย'!A5:U19,5,FALSE),"ผอม",IF(K21<=VLOOKUP(F21,'เกณฑ์ดัชนีมวลกาย'!A5:U19,7,FALSE),"สมส่วน",IF(K21<=VLOOKUP(F21,'เกณฑ์ดัชนีมวลกาย'!A5:U19,9,FALSE),"ท้วม","อ้วน")))),IF(K21<=VLOOKUP(F21,'เกณฑ์ดัชนีมวลกาย'!A5:U19,13,FALSE),"ผอมมาก",IF(K21<=VLOOKUP(F21,'เกณฑ์ดัชนีมวลกาย'!A5:U19,15,FALSE),"ผอม",IF(K21<=VLOOKUP(F21,'เกณฑ์ดัชนีมวลกาย'!A5:U19,17,FALSE),"สมส่วน",IF(K21<=VLOOKUP(F21,'เกณฑ์ดัชนีมวลกาย'!A5:U19,19,FALSE),"ท้วม","อ้วน")))))) -> สมส่วน | M21: =IF($B21="","",IF($C21="ชาย",IF(J21<=VLOOKUP(F21,'เกณฑ์ส่วนสูง'!A5:U19,3,FALSE),"เตี้ย",IF(J21<=VLOOKUP(F21,'เกณฑ์ส่วนสูง'!A5:U19,5,FALSE),"ค่อนข้างเตี้ย",IF(J21<=VLOOKUP(F21,'เกณฑ์ส่วนสูง'!A5:U19,7,FALSE),"ส่วนสูงตามเกณฑ์",IF(J21<=VLOOKUP(F21,'เกณฑ์ส่วนสูง'!A5:U19,9,FALSE),"ค่อนข้างสูง","สูง")))),IF(J21<=VLOOKUP(F21,'เกณฑ์ส่วนสูง'!A5:U19,13,FALSE),"เตี้ย",IF(J21<=VLOOKUP(F21,'เกณฑ์ส่วนสูง'!A5:U19,15,FALSE),"ค่อนข้างเตี้ย",IF(J21<=VLOOKUP(F21,'เกณฑ์ส่วนสูง'!A5:U19,17,FALSE),"ส่วนสูงตามเกณฑ์",IF(J21<=VLOOKUP(F21,'เกณฑ์ส่วนสูง'!A5:U19,19,FALSE),"ค่อนข้างสูง","สูง")))))) -> ส่วนสูงตามเกณฑ์
A22: 16 | B22: ='ข้อมูล'!C20 -> ด.ญ.ห้องเรียน วิชาการ | C22: ='ข้อมูล'!D20 -> หญิง | D22: ='ข้อมูล'!E20 -> 39862 | E22: 45071 | F22: =DATEDIF(D22,E22,"y") -> 14 | G22: =DATEDIF(D22,E22,"ym") -> 3 | H22: =DATEDIF(D22,E22,"md") -> 7 | I22: 46 | J22: 159 | K22: =IF(B22="","",I22/((J22/100)^2)) -> 18.195483 | L22: =IF($B22="","",IF($C22="ชาย",IF(K22<=VLOOKUP(F22,'เกณฑ์ดัชนีมวลกาย'!A5:U19,3,FALSE),"ผอมมาก",IF(K22<=VLOOKUP(F22,'เกณฑ์ดัชนีมวลกาย'!A5:U19,5,FALSE),"ผอม",IF(K22<=VLOOKUP(F22,'เกณฑ์ดัชนีมวลกาย'!A5:U19,7,FALSE),"สมส่วน",IF(K22<=VLOOKUP(F22,'เกณฑ์ดัชนีมวลกาย'!A5:U19,9,FALSE),"ท้วม","อ้วน")))),IF(K22<=VLOOKUP(F22,'เกณฑ์ดัชนีมวลกาย'!A5:U19,13,FALSE),"ผอมมาก",IF(K22<=VLOOKUP(F22,'เกณฑ์ดัชนีมวลกาย'!A5:U19,15,FALSE),"ผอม",IF(K22<=VLOOKUP(F22,'เกณฑ์ดัชนีมวลกาย'!A5:U19,17,FALSE),"สมส่วน",IF(K22<=VLOOKUP(F22,'เกณฑ์ดัชนีมวลกาย'!A5:U19,19,FALSE),"ท้วม","อ้วน")))))) -> สมส่วน | M22: =IF($B22="","",IF($C22="ชาย",IF(J22<=VLOOKUP(F22,'เกณฑ์ส่วนสูง'!A5:U19,3,FALSE),"เตี้ย",IF(J22<=VLOOKUP(F22,'เกณฑ์ส่วนสูง'!A5:U19,5,FALSE),"ค่อนข้างเตี้ย",IF(J22<=VLOOKUP(F22,'เกณฑ์ส่วนสูง'!A5:U19,7,FALSE),"ส่วนสูงตามเกณฑ์",IF(J22<=VLOOKUP(F22,'เกณฑ์ส่วนสูง'!A5:U19,9,FALSE),"ค่อนข้างสูง","สูง")))),IF(J22<=VLOOKUP(F22,'เกณฑ์ส่วนสูง'!A5:U19,13,FALSE),"เตี้ย",IF(J22<=VLOOKUP(F22,'เกณฑ์ส่วนสูง'!A5:U19,15,FALSE),"ค่อนข้างเตี้ย",IF(J22<=VLOOKUP(F22,'เกณฑ์ส่วนสูง'!A5:U19,17,FALSE),"ส่วนสูงตามเกณฑ์",IF(J22<=VLOOKUP(F22,'เกณฑ์ส่วนสูง'!A5:U19,19,FALSE),"ค่อนข้างสูง","สูง")))))) -> ส่วนสูงตามเกณฑ์
A23: 17 | B23: ='ข้อมูล'!C21 -> ด.ญ.ห้องเรียน วิชาการ | C23: ='ข้อมูล'!D21 -> หญิง | D23: ='ข้อมูล'!E21 -> 39863 | E23: 45071 | F23: =DATEDIF(D23,E23,"y") -> 14 | G23: =DATEDIF(D23,E23,"ym") -> 3 | H23: =DATEDIF(D23,E23,"md") -> 6 | I23: 46 | J23: 159 | K23: =IF(B23="","",I23/((J23/100)^2)) -> 18.195483 | L23: =IF($B23="","",IF($C23="ชาย",IF(K23<=VLOOKUP(F23,'เกณฑ์ดัชนีมวลกาย'!A5:U19,3,FALSE),"ผอมมาก",IF(K23<=VLOOKUP(F23,'เกณฑ์ดัชนีมวลกาย'!A5:U19,5,FALSE),"ผอม",IF(K23<=VLOOKUP(F23,'เกณฑ์ดัชนีมวลกาย'!A5:U19,7,FALSE),"สมส่วน",IF(K23<=VLOOKUP(F23,'เกณฑ์ดัชนีมวลกาย'!A5:U19,9,FALSE),"ท้วม","อ้วน")))),IF(K23<=VLOOKUP(F23,'เกณฑ์ดัชนีมวลกาย'!A5:U19,13,FALSE),"ผอมมาก",IF(K23<=VLOOKUP(F23,'เกณฑ์ดัชนีมวลกาย'!A5:U19,15,FALSE),"ผอม",IF(K23<=VLOOKUP(F23,'เกณฑ์ดัชนีมวลกาย'!A5:U19,17,FALSE),"สมส่วน",IF(K23<=VLOOKUP(F23,'เกณฑ์ดัชนีมวลกาย'!A5:U19,19,FALSE),"ท้วม","อ้วน")))))) -> สมส่วน | M23: =IF($B23="","",IF($C23="ชาย",IF(J23<=VLOOKUP(F23,'เกณฑ์ส่วนสูง'!A5:U19,3,FALSE),"เตี้ย",IF(J23<=VLOOKUP(F23,'เกณฑ์ส่วนสูง'!A5:U19,5,FALSE),"ค่อนข้างเตี้ย",IF(J23<=VLOOKUP(F23,'เกณฑ์ส่วนสูง'!A5:U19,7,FALSE),"ส่วนสูงตามเกณฑ์",IF(J23<=VLOOKUP(F23,'เกณฑ์ส่วนสูง'!A5:U19,9,FALSE),"ค่อนข้างสูง","สูง")))),IF(J23<=VLOOKUP(F23,'เกณฑ์ส่วนสูง'!A5:U19,13,FALSE),"เตี้ย",IF(J23<=VLOOKUP(F23,'เกณฑ์ส่วนสูง'!A5:U19,15,FALSE),"ค่อนข้างเตี้ย",IF(J23<=VLOOKUP(F23,'เกณฑ์ส่วนสูง'!A5:U19,17,FALSE),"ส่วนสูงตามเกณฑ์",IF(J23<=VLOOKUP(F23,'เกณฑ์ส่วนสูง'!A5:U19,19,FALSE),"ค่อนข้างสูง","สูง")))))) -> ส่วนสูงตามเกณฑ์
A24: 18 | B24: ='ข้อมูล'!C22 | C24: ='ข้อมูล'!D22 | L24: =IF($B24="","",IF($C24="ชาย",IF(K24<=VLOOKUP(F24,'เกณฑ์ดัชนีมวลกาย'!A5:U19,3,FALSE),"ผอมมาก",IF(K24<=VLOOKUP(F24,'เกณฑ์ดัชนีมวลกาย'!A5:U19,5,FALSE),"ผอม",IF(K24<=VLOOKUP(F24,'เกณฑ์ดัชนีมวลกาย'!A5:U19,7,FALSE),"สมส่วน",IF(K24<=VLOOKUP(F24,'เกณฑ์ดัชนีมวลกาย'!A5:U19,9,FALSE),"ท้วม","อ้วน")))),IF(K24<=VLOOKUP(F24,'เกณฑ์ดัชนีมวลกาย'!A5:U19,13,FALSE),"ผอมมาก",IF(K24<=VLOOKUP(F24,'เกณฑ์ดัชนีมวลกาย'!A5:U19,15,FALSE),"ผอม",IF(K24<=VLOOKUP(F24,'เกณฑ์ดัชนีมวลกาย'!A5:U19,17,FALSE),"สมส่วน",IF(K24<=VLOOKUP(F24,'เกณฑ์ดัชนีมวลกาย'!A5:U19,19,FALSE),"ท้วม","อ้วน")))))) | M24: =IF($B24="","",IF($C24="ชาย",IF(J24<=VLOOKUP(F24,'เกณฑ์ส่วนสูง'!A5:U19,3,FALSE),"เตี้ย",IF(J24<=VLOOKUP(F24,'เกณฑ์ส่วนสูง'!A5:U19,5,FALSE),"ค่อนข้างเตี้ย",IF(J24<=VLOOKUP(F24,'เกณฑ์ส่วนสูง'!A5:U19,7,FALSE),"ส่วนสูงตามเกณฑ์",IF(J24<=VLOOKUP(F24,'เกณฑ์ส่วนสูง'!A5:U19,9,FALSE),"ค่อนข้างสูง","สูง")))),IF(J24<=VLOOKUP(F24,'เกณฑ์ส่วนสูง'!A5:U19,13,FALSE),"เตี้ย",IF(J24<=VLOOKUP(F24,'เกณฑ์ส่วนสูง'!A5:U19,15,FALSE),"ค่อนข้างเตี้ย",IF(J24<=VLOOKUP(F24,'เกณฑ์ส่วนสูง'!A5:U19,17,FALSE),"ส่วนสูงตามเกณฑ์",IF(J24<=VLOOKUP(F24,'เกณฑ์ส่วนสูง'!A5:U19,19,FALSE),"ค่อนข้างสูง","สูง"))))))
A25: 19 | B25: ='ข้อมูล'!C23 | C25: ='ข้อมูล'!D23 | L25: =IF($B25="","",IF($C25="ชาย",IF(K25<=VLOOKUP(F25,'เกณฑ์ดัชนีมวลกาย'!A5:U19,3,FALSE),"ผอมมาก",IF(K25<=VLOOKUP(F25,'เกณฑ์ดัชนีมวลกาย'!A5:U19,5,FALSE),"ผอม",IF(K25<=VLOOKUP(F25,'เกณฑ์ดัชนีมวลกาย'!A5:U19,7,FALSE),"สมส่วน",IF(K25<=VLOOKUP(F25,'เกณฑ์ดัชนีมวลกาย'!A5:U19,9,FALSE),"ท้วม","อ้วน")))),IF(K25<=VLOOKUP(F25,'เกณฑ์ดัชนีมวลกาย'!A5:U19,13,FALSE),"ผอมมาก",IF(K25<=VLOOKUP(F25,'เกณฑ์ดัชนีมวลกาย'!A5:U19,15,FALSE),"ผอม",IF(K25<=VLOOKUP(F25,'เกณฑ์ดัชนีมวลกาย'!A5:U19,17,FALSE),"สมส่วน",IF(K25<=VLOOKUP(F25,'เกณฑ์ดัชนีมวลกาย'!A5:U19,19,FALSE),"ท้วม","อ้วน")))))) | M25: =IF($B25="","",IF($C25="ชาย",IF(J25<=VLOOKUP(F25,'เกณฑ์ส่วนสูง'!A5:U19,3,FALSE),"เตี้ย",IF(J25<=VLOOKUP(F25,'เกณฑ์ส่วนสูง'!A5:U19,5,FALSE),"ค่อนข้างเตี้ย",IF(J25<=VLOOKUP(F25,'เกณฑ์ส่วนสูง'!A5:U19,7,FALSE),"ส่วนสูงตามเกณฑ์",IF(J25<=VLOOKUP(F25,'เกณฑ์ส่วนสูง'!A5:U19,9,FALSE),"ค่อนข้างสูง","สูง")))),IF(J25<=VLOOKUP(F25,'เกณฑ์ส่วนสูง'!A5:U19,13,FALSE),"เตี้ย",IF(J25<=VLOOKUP(F25,'เกณฑ์ส่วนสูง'!A5:U19,15,FALSE),"ค่อนข้างเตี้ย",IF(J25<=VLOOKUP(F25,'เกณฑ์ส่วนสูง'!A5:U19,17,FALSE),"ส่วนสูงตามเกณฑ์",IF(J25<=VLOOKUP(F25,'เกณฑ์ส่วนสูง'!A5:U19,19,FALSE),"ค่อนข้างสูง","สูง"))))))
A26: 20 | B26: ='ข้อมูล'!C24 | C26: ='ข้อมูล'!D24 | L26: =IF($B26="","",IF($C26="ชาย",IF(K26<=VLOOKUP(F26,'เกณฑ์ดัชนีมวลกาย'!A5:U19,3,FALSE),"ผอมมาก",IF(K26<=VLOOKUP(F26,'เกณฑ์ดัชนีมวลกาย'!A5:U19,5,FALSE),"ผอม",IF(K26<=VLOOKUP(F26,'เกณฑ์ดัชนีมวลกาย'!A5:U19,7,FALSE),"สมส่วน",IF(K26<=VLOOKUP(F26,'เกณฑ์ดัชนีมวลกาย'!A5:U19,9,FALSE),"ท้วม","อ้วน")))),IF(K26<=VLOOKUP(F26,'เกณฑ์ดัชนีมวลกาย'!A5:U19,13,FALSE),"ผอมมาก",IF(K26<=VLOOKUP(F26,'เกณฑ์ดัชนีมวลกาย'!A5:U19,15,FALSE),"ผอม",IF(K26<=VLOOKUP(F26,'เกณฑ์ดัชนีมวลกาย'!A5:U19,17,FALSE),"สมส่วน",IF(K26<=VLOOKUP(F26,'เกณฑ์ดัชนีมวลกาย'!A5:U19,19,FALSE),"ท้วม","อ้วน")))))) | M26: =IF($B26="","",IF($C26="ชาย",IF(J26<=VLOOKUP(F26,'เกณฑ์ส่วนสูง'!A5:U19,3,FALSE),"เตี้ย",IF(J26<=VLOOKUP(F26,'เกณฑ์ส่วนสูง'!A5:U19,5,FALSE),"ค่อนข้างเตี้ย",IF(J26<=VLOOKUP(F26,'เกณฑ์ส่วนสูง'!A5:U19,7,FALSE),"ส่วนสูงตามเกณฑ์",IF(J26<=VLOOKUP(F26,'เกณฑ์ส่วนสูง'!A5:U19,9,FALSE),"ค่อนข้างสูง","สูง")))),IF(J26<=VLOOKUP(F26,'เกณฑ์ส่วนสูง'!A5:U19,13,FALSE),"เตี้ย",IF(J26<=VLOOKUP(F26,'เกณฑ์ส่วนสูง'!A5:U19,15,FALSE),"ค่อนข้างเตี้ย",IF(J26<=VLOOKUP(F26,'เกณฑ์ส่วนสูง'!A5:U19,17,FALSE),"ส่วนสูงตามเกณฑ์",IF(J26<=VLOOKUP(F26,'เกณฑ์ส่วนสูง'!A5:U19,19,FALSE),"ค่อนข้างสูง","สูง"))))))
A27: 21 | B27: ='ข้อมูล'!C25 | C27: ='ข้อมูล'!D25 | L27: =IF($B27="","",IF($C27="ชาย",IF(K27<=VLOOKUP(F27,'เกณฑ์ดัชนีมวลกาย'!A5:U19,3,FALSE),"ผอมมาก",IF(K27<=VLOOKUP(F27,'เกณฑ์ดัชนีมวลกาย'!A5:U19,5,FALSE),"ผอม",IF(K27<=VLOOKUP(F27,'เกณฑ์ดัชนีมวลกาย'!A5:U19,7,FALSE),"สมส่วน",IF(K27<=VLOOKUP(F27,'เกณฑ์ดัชนีมวลกาย'!A5:U19,9,FALSE),"ท้วม","อ้วน")))),IF(K27<=VLOOKUP(F27,'เกณฑ์ดัชนีมวลกาย'!A5:U19,13,FALSE),"ผอมมาก",IF(K27<=VLOOKUP(F27,'เกณฑ์ดัชนีมวลกาย'!A5:U19,15,FALSE),"ผอม",IF(K27<=VLOOKUP(F27,'เกณฑ์ดัชนีมวลกาย'!A5:U19,17,FALSE),"สมส่วน",IF(K27<=VLOOKUP(F27,'เกณฑ์ดัชนีมวลกาย'!A5:U19,19,FALSE),"ท้วม","อ้วน")))))) | M27: =IF($B27="","",IF($C27="ชาย",IF(J27<=VLOOKUP(F27,'เกณฑ์ส่วนสูง'!A5:U19,3,FALSE),"เตี้ย",IF(J27<=VLOOKUP(F27,'เกณฑ์ส่วนสูง'!A5:U19,5,FALSE),"ค่อนข้างเตี้ย",IF(J27<=VLOOKUP(F27,'เกณฑ์ส่วนสูง'!A5:U19,7,FALSE),"ส่วนสูงตามเกณฑ์",IF(J27<=VLOOKUP(F27,'เกณฑ์ส่วนสูง'!A5:U19,9,FALSE),"ค่อนข้างสูง","สูง")))),IF(J27<=VLOOKUP(F27,'เกณฑ์ส่วนสูง'!A5:U19,13,FALSE),"เตี้ย",IF(J27<=VLOOKUP(F27,'เกณฑ์ส่วนสูง'!A5:U19,15,FALSE),"ค่อนข้างเตี้ย",IF(J27<=VLOOKUP(F27,'เกณฑ์ส่วนสูง'!A5:U19,17,FALSE),"ส่วนสูงตามเกณฑ์",IF(J27<=VLOOKUP(F27,'เกณฑ์ส่วนสูง'!A5:U19,19,FALSE),"ค่อนข้างสูง","สูง"))))))
A28: 22 | B28: ='ข้อมูล'!C26 | C28: ='ข้อมูล'!D26 | L28: =IF($B28="","",IF($C28="ชาย",IF(K28<=VLOOKUP(F28,'เกณฑ์ดัชนีมวลกาย'!A5:U19,3,FALSE),"ผอมมาก",IF(K28<=VLOOKUP(F28,'เกณฑ์ดัชนีมวลกาย'!A5:U19,5,FALSE),"ผอม",IF(K28<=VLOOKUP(F28,'เกณฑ์ดัชนีมวลกาย'!A5:U19,7,FALSE),"สมส่วน",IF(K28<=VLOOKUP(F28,'เกณฑ์ดัชนีมวลกาย'!A5:U19,9,FALSE),"ท้วม","อ้วน")))),IF(K28<=VLOOKUP(F28,'เกณฑ์ดัชนีมวลกาย'!A5:U19,13,FALSE),"ผอมมาก",IF(K28<=VLOOKUP(F28,'เกณฑ์ดัชนีมวลกาย'!A5:U19,15,FALSE),"ผอม",IF(K28<=VLOOKUP(F28,'เกณฑ์ดัชนีมวลกาย'!A5:U19,17,FALSE),"สมส่วน",IF(K28<=VLOOKUP(F28,'เกณฑ์ดัชนีมวลกาย'!A5:U19,19,FALSE),"ท้วม","อ้วน")))))) | M28: =IF($B28="","",IF($C28="ชาย",IF(J28<=VLOOKUP(F28,'เกณฑ์ส่วนสูง'!A5:U19,3,FALSE),"เตี้ย",IF(J28<=VLOOKUP(F28,'เกณฑ์ส่วนสูง'!A5:U19,5,FALSE),"ค่อนข้างเตี้ย",IF(J28<=VLOOKUP(F28,'เกณฑ์ส่วนสูง'!A5:U19,7,FALSE),"ส่วนสูงตามเกณฑ์",IF(J28<=VLOOKUP(F28,'เกณฑ์ส่วนสูง'!A5:U19,9,FALSE),"ค่อนข้างสูง","สูง")))),IF(J28<=VLOOKUP(F28,'เกณฑ์ส่วนสูง'!A5:U19,13,FALSE),"เตี้ย",IF(J28<=VLOOKUP(F28,'เกณฑ์ส่วนสูง'!A5:U19,15,FALSE),"ค่อนข้างเตี้ย",IF(J28<=VLOOKUP(F28,'เกณฑ์ส่วนสูง'!A5:U19,17,FALSE),"ส่วนสูงตามเกณฑ์",IF(J28<=VLOOKUP(F28,'เกณฑ์ส่วนสูง'!A5:U19,19,FALSE),"ค่อนข้างสูง","สูง"))))))
A29: 23 | B29: ='ข้อมูล'!C27 | C29: ='ข้อมูล'!D27 | L29: =IF($B29="","",IF($C29="ชาย",IF(K29<=VLOOKUP(F29,'เกณฑ์ดัชนีมวลกาย'!A5:U19,3,FALSE),"ผอมมาก",IF(K29<=VLOOKUP(F29,'เกณฑ์ดัชนีมวลกาย'!A5:U19,5,FALSE),"ผอม",IF(K29<=VLOOKUP(F29,'เกณฑ์ดัชนีมวลกาย'!A5:U19,7,FALSE),"สมส่วน",IF(K29<=VLOOKUP(F29,'เกณฑ์ดัชนีมวลกาย'!A5:U19,9,FALSE),"ท้วม","อ้วน")))),IF(K29<=VLOOKUP(F29,'เกณฑ์ดัชนีมวลกาย'!A5:U19,13,FALSE),"ผอมมาก",IF(K29<=VLOOKUP(F29,'เกณฑ์ดัชนีมวลกาย'!A5:U19,15,FALSE),"ผอม",IF(K29<=VLOOKUP(F29,'เกณฑ์ดัชนีมวลกาย'!A5:U19,17,FALSE),"สมส่วน",IF(K29<=VLOOKUP(F29,'เกณฑ์ดัชนีมวลกาย'!A5:U19,19,FALSE),"ท้วม","อ้วน")))))) | M29: =IF($B29="","",IF($C29="ชาย",IF(J29<=VLOOKUP(F29,'เกณฑ์ส่วนสูง'!A5:U19,3,FALSE),"เตี้ย",IF(J29<=VLOOKUP(F29,'เกณฑ์ส่วนสูง'!A5:U19,5,FALSE),"ค่อนข้างเตี้ย",IF(J29<=VLOOKUP(F29,'เกณฑ์ส่วนสูง'!A5:U19,7,FALSE),"ส่วนสูงตามเกณฑ์",IF(J29<=VLOOKUP(F29,'เกณฑ์ส่วนสูง'!A5:U19,9,FALSE),"ค่อนข้างสูง","สูง")))),IF(J29<=VLOOKUP(F29,'เกณฑ์ส่วนสูง'!A5:U19,13,FALSE),"เตี้ย",IF(J29<=VLOOKUP(F29,'เกณฑ์ส่วนสูง'!A5:U19,15,FALSE),"ค่อนข้างเตี้ย",IF(J29<=VLOOKUP(F29,'เกณฑ์ส่วนสูง'!A5:U19,17,FALSE),"ส่วนสูงตามเกณฑ์",IF(J29<=VLOOKUP(F29,'เกณฑ์ส่วนสูง'!A5:U19,19,FALSE),"ค่อนข้างสูง","สูง"))))))
A30: 24 | B30: ='ข้อมูล'!C28 | C30: ='ข้อมูล'!D28 | L30: =IF($B30="","",IF($C30="ชาย",IF(K30<=VLOOKUP(F30,'เกณฑ์ดัชนีมวลกาย'!A5:U19,3,FALSE),"ผอมมาก",IF(K30<=VLOOKUP(F30,'เกณฑ์ดัชนีมวลกาย'!A5:U19,5,FALSE),"ผอม",IF(K30<=VLOOKUP(F30,'เกณฑ์ดัชนีมวลกาย'!A5:U19,7,FALSE),"สมส่วน",IF(K30<=VLOOKUP(F30,'เกณฑ์ดัชนีมวลกาย'!A5:U19,9,FALSE),"ท้วม","อ้วน")))),IF(K30<=VLOOKUP(F30,'เกณฑ์ดัชนีมวลกาย'!A5:U19,13,FALSE),"ผอมมาก",IF(K30<=VLOOKUP(F30,'เกณฑ์ดัชนีมวลกาย'!A5:U19,15,FALSE),"ผอม",IF(K30<=VLOOKUP(F30,'เกณฑ์ดัชนีมวลกาย'!A5:U19,17,FALSE),"สมส่วน",IF(K30<=VLOOKUP(F30,'เกณฑ์ดัชนีมวลกาย'!A5:U19,19,FALSE),"ท้วม","อ้วน")))))) | M30: =IF($B30="","",IF($C30="ชาย",IF(J30<=VLOOKUP(F30,'เกณฑ์ส่วนสูง'!A5:U19,3,FALSE),"เตี้ย",IF(J30<=VLOOKUP(F30,'เกณฑ์ส่วนสูง'!A5:U19,5,FALSE),"ค่อนข้างเตี้ย",IF(J30<=VLOOKUP(F30,'เกณฑ์ส่วนสูง'!A5:U19,7,FALSE),"ส่วนสูงตามเกณฑ์",IF(J30<=VLOOKUP(F30,'เกณฑ์ส่วนสูง'!A5:U19,9,FALSE),"ค่อนข้างสูง","สูง")))),IF(J30<=VLOOKUP(F30,'เกณฑ์ส่วนสูง'!A5:U19,13,FALSE),"เตี้ย",IF(J30<=VLOOKUP(F30,'เกณฑ์ส่วนสูง'!A5:U19,15,FALSE),"ค่อนข้างเตี้ย",IF(J30<=VLOOKUP(F30,'เกณฑ์ส่วนสูง'!A5:U19,17,FALSE),"ส่วนสูงตามเกณฑ์",IF(J30<=VLOOKUP(F30,'เกณฑ์ส่วนสูง'!A5:U19,19,FALSE),"ค่อนข้างสูง","สูง"))))))
A31: 25 | B31: ='ข้อมูล'!C29 | C31: ='ข้อมูล'!D29 | L31: =IF($B31="","",IF($C31="ชาย",IF(K31<=VLOOKUP(F31,'เกณฑ์ดัชนีมวลกาย'!A5:U19,3,FALSE),"ผอมมาก",IF(K31<=VLOOKUP(F31,'เกณฑ์ดัชนีมวลกาย'!A5:U19,5,FALSE),"ผอม",IF(K31<=VLOOKUP(F31,'เกณฑ์ดัชนีมวลกาย'!A5:U19,7,FALSE),"สมส่วน",IF(K31<=VLOOKUP(F31,'เกณฑ์ดัชนีมวลกาย'!A5:U19,9,FALSE),"ท้วม","อ้วน")))),IF(K31<=VLOOKUP(F31,'เกณฑ์ดัชนีมวลกาย'!A5:U19,13,FALSE),"ผอมมาก",IF(K31<=VLOOKUP(F31,'เกณฑ์ดัชนีมวลกาย'!A5:U19,15,FALSE),"ผอม",IF(K31<=VLOOKUP(F31,'เกณฑ์ดัชนีมวลกาย'!A5:U19,17,FALSE),"สมส่วน",IF(K31<=VLOOKUP(F31,'เกณฑ์ดัชนีมวลกาย'!A5:U19,19,FALSE),"ท้วม","อ้วน")))))) | M31: =IF($B31="","",IF($C31="ชาย",IF(J31<=VLOOKUP(F31,'เกณฑ์ส่วนสูง'!A5:U19,3,FALSE),"เตี้ย",IF(J31<=VLOOKUP(F31,'เกณฑ์ส่วนสูง'!A5:U19,5,FALSE),"ค่อนข้างเตี้ย",IF(J31<=VLOOKUP(F31,'เกณฑ์ส่วนสูง'!A5:U19,7,FALSE),"ส่วนสูงตามเกณฑ์",IF(J31<=VLOOKUP(F31,'เกณฑ์ส่วนสูง'!A5:U19,9,FALSE),"ค่อนข้างสูง","สูง")))),IF(J31<=VLOOKUP(F31,'เกณฑ์ส่วนสูง'!A5:U19,13,FALSE),"เตี้ย",IF(J31<=VLOOKUP(F31,'เกณฑ์ส่วนสูง'!A5:U19,15,FALSE),"ค่อนข้างเตี้ย",IF(J31<=VLOOKUP(F31,'เกณฑ์ส่วนสูง'!A5:U19,17,FALSE),"ส่วนสูงตามเกณฑ์",IF(J31<=VLOOKUP(F31,'เกณฑ์ส่วนสูง'!A5:U19,19,FALSE),"ค่อนข้างสูง","สูง"))))))
A32: 26 | B32: ='ข้อมูล'!C30 | C32: ='ข้อมูล'!D30 | L32: =IF($B32="","",IF($C32="ชาย",IF(K32<=VLOOKUP(F32,'เกณฑ์ดัชนีมวลกาย'!A5:U19,3,FALSE),"ผอมมาก",IF(K32<=VLOOKUP(F32,'เกณฑ์ดัชนีมวลกาย'!A5:U19,5,FALSE),"ผอม",IF(K32<=VLOOKUP(F32,'เกณฑ์ดัชนีมวลกาย'!A5:U19,7,FALSE),"สมส่วน",IF(K32<=VLOOKUP(F32,'เกณฑ์ดัชนีมวลกาย'!A5:U19,9,FALSE),"ท้วม","อ้วน")))),IF(K32<=VLOOKUP(F32,'เกณฑ์ดัชนีมวลกาย'!A5:U19,13,FALSE),"ผอมมาก",IF(K32<=VLOOKUP(F32,'เกณฑ์ดัชนีมวลกาย'!A5:U19,15,FALSE),"ผอม",IF(K32<=VLOOKUP(F32,'เกณฑ์ดัชนีมวลกาย'!A5:U19,17,FALSE),"สมส่วน",IF(K32<=VLOOKUP(F32,'เกณฑ์ดัชนีมวลกาย'!A5:U19,19,FALSE),"ท้วม","อ้วน")))))) | M32: =IF($B32="","",IF($C32="ชาย",IF(J32<=VLOOKUP(F32,'เกณฑ์ส่วนสูง'!A5:U19,3,FALSE),"เตี้ย",IF(J32<=VLOOKUP(F32,'เกณฑ์ส่วนสูง'!A5:U19,5,FALSE),"ค่อนข้างเตี้ย",IF(J32<=VLOOKUP(F32,'เกณฑ์ส่วนสูง'!A5:U19,7,FALSE),"ส่วนสูงตามเกณฑ์",IF(J32<=VLOOKUP(F32,'เกณฑ์ส่วนสูง'!A5:U19,9,FALSE),"ค่อนข้างสูง","สูง")))),IF(J32<=VLOOKUP(F32,'เกณฑ์ส่วนสูง'!A5:U19,13,FALSE),"เตี้ย",IF(J32<=VLOOKUP(F32,'เกณฑ์ส่วนสูง'!A5:U19,15,FALSE),"ค่อนข้างเตี้ย",IF(J32<=VLOOKUP(F32,'เกณฑ์ส่วนสูง'!A5:U19,17,FALSE),"ส่วนสูงตามเกณฑ์",IF(J32<=VLOOKUP(F32,'เกณฑ์ส่วนสูง'!A5:U19,19,FALSE),"ค่อนข้างสูง","สูง"))))))
A33: 27 | B33: ='ข้อมูล'!C31 | C33: ='ข้อมูล'!D31 | L33: =IF($B33="","",IF($C33="ชาย",IF(K33<=VLOOKUP(F33,'เกณฑ์ดัชนีมวลกาย'!A5:U19,3,FALSE),"ผอมมาก",IF(K33<=VLOOKUP(F33,'เกณฑ์ดัชนีมวลกาย'!A5:U19,5,FALSE),"ผอม",IF(K33<=VLOOKUP(F33,'เกณฑ์ดัชนีมวลกาย'!A5:U19,7,FALSE),"สมส่วน",IF(K33<=VLOOKUP(F33,'เกณฑ์ดัชนีมวลกาย'!A5:U19,9,FALSE),"ท้วม","อ้วน")))),IF(K33<=VLOOKUP(F33,'เกณฑ์ดัชนีมวลกาย'!A5:U19,13,FALSE),"ผอมมาก",IF(K33<=VLOOKUP(F33,'เกณฑ์ดัชนีมวลกาย'!A5:U19,15,FALSE),"ผอม",IF(K33<=VLOOKUP(F33,'เกณฑ์ดัชนีมวลกาย'!A5:U19,17,FALSE),"สมส่วน",IF(K33<=VLOOKUP(F33,'เกณฑ์ดัชนีมวลกาย'!A5:U19,19,FALSE),"ท้วม","อ้วน")))))) | M33: =IF($B33="","",IF($C33="ชาย",IF(J33<=VLOOKUP(F33,'เกณฑ์ส่วนสูง'!A5:U19,3,FALSE),"เตี้ย",IF(J33<=VLOOKUP(F33,'เกณฑ์ส่วนสูง'!A5:U19,5,FALSE),"ค่อนข้างเตี้ย",IF(J33<=VLOOKUP(F33,'เกณฑ์ส่วนสูง'!A5:U19,7,FALSE),"ส่วนสูงตามเกณฑ์",IF(J33<=VLOOKUP(F33,'เกณฑ์ส่วนสูง'!A5:U19,9,FALSE),"ค่อนข้างสูง","สูง")))),IF(J33<=VLOOKUP(F33,'เกณฑ์ส่วนสูง'!A5:U19,13,FALSE),"เตี้ย",IF(J33<=VLOOKUP(F33,'เกณฑ์ส่วนสูง'!A5:U19,15,FALSE),"ค่อนข้างเตี้ย",IF(J33<=VLOOKUP(F33,'เกณฑ์ส่วนสูง'!A5:U19,17,FALSE),"ส่วนสูงตามเกณฑ์",IF(J33<=VLOOKUP(F33,'เกณฑ์ส่วนสูง'!A5:U19,19,FALSE),"ค่อนข้างสูง","สูง"))))))
A34: 28 | B34: ='ข้อมูล'!C32 | C34: ='ข้อมูล'!D32 | L34: =IF($B34="","",IF($C34="ชาย",IF(K34<=VLOOKUP(F34,'เกณฑ์ดัชนีมวลกาย'!A5:U19,3,FALSE),"ผอมมาก",IF(K34<=VLOOKUP(F34,'เกณฑ์ดัชนีมวลกาย'!A5:U19,5,FALSE),"ผอม",IF(K34<=VLOOKUP(F34,'เกณฑ์ดัชนีมวลกาย'!A5:U19,7,FALSE),"สมส่วน",IF(K34<=VLOOKUP(F34,'เกณฑ์ดัชนีมวลกาย'!A5:U19,9,FALSE),"ท้วม","อ้วน")))),IF(K34<=VLOOKUP(F34,'เกณฑ์ดัชนีมวลกาย'!A5:U19,13,FALSE),"ผอมมาก",IF(K34<=VLOOKUP(F34,'เกณฑ์ดัชนีมวลกาย'!A5:U19,15,FALSE),"ผอม",IF(K34<=VLOOKUP(F34,'เกณฑ์ดัชนีมวลกาย'!A5:U19,17,FALSE),"สมส่วน",IF(K34<=VLOOKUP(F34,'เกณฑ์ดัชนีมวลกาย'!A5:U19,19,FALSE),"ท้วม","อ้วน")))))) | M34: =IF($B34="","",IF($C34="ชาย",IF(J34<=VLOOKUP(F34,'เกณฑ์ส่วนสูง'!A5:U19,3,FALSE),"เตี้ย",IF(J34<=VLOOKUP(F34,'เกณฑ์ส่วนสูง'!A5:U19,5,FALSE),"ค่อนข้างเตี้ย",IF(J34<=VLOOKUP(F34,'เกณฑ์ส่วนสูง'!A5:U19,7,FALSE),"ส่วนสูงตามเกณฑ์",IF(J34<=VLOOKUP(F34,'เกณฑ์ส่วนสูง'!A5:U19,9,FALSE),"ค่อนข้างสูง","สูง")))),IF(J34<=VLOOKUP(F34,'เกณฑ์ส่วนสูง'!A5:U19,13,FALSE),"เตี้ย",IF(J34<=VLOOKUP(F34,'เกณฑ์ส่วนสูง'!A5:U19,15,FALSE),"ค่อนข้างเตี้ย",IF(J34<=VLOOKUP(F34,'เกณฑ์ส่วนสูง'!A5:U19,17,FALSE),"ส่วนสูงตามเกณฑ์",IF(J34<=VLOOKUP(F34,'เกณฑ์ส่วนสูง'!A5:U19,19,FALSE),"ค่อนข้างสูง","สูง"))))))
A35: 29 | B35: ='ข้อมูล'!C33 | C35: ='ข้อมูล'!D33 | L35: =IF($B35="","",IF($C35="ชาย",IF(K35<=VLOOKUP(F35,'เกณฑ์ดัชนีมวลกาย'!A5:U19,3,FALSE),"ผอมมาก",IF(K35<=VLOOKUP(F35,'เกณฑ์ดัชนีมวลกาย'!A5:U19,5,FALSE),"ผอม",IF(K35<=VLOOKUP(F35,'เกณฑ์ดัชนีมวลกาย'!A5:U19,7,FALSE),"สมส่วน",IF(K35<=VLOOKUP(F35,'เกณฑ์ดัชนีมวลกาย'!A5:U19,9,FALSE),"ท้วม","อ้วน")))),IF(K35<=VLOOKUP(F35,'เกณฑ์ดัชนีมวลกาย'!A5:U19,13,FALSE),"ผอมมาก",IF(K35<=VLOOKUP(F35,'เกณฑ์ดัชนีมวลกาย'!A5:U19,15,FALSE),"ผอม",IF(K35<=VLOOKUP(F35,'เกณฑ์ดัชนีมวลกาย'!A5:U19,17,FALSE),"สมส่วน",IF(K35<=VLOOKUP(F35,'เกณฑ์ดัชนีมวลกาย'!A5:U19,19,FALSE),"ท้วม","อ้วน")))))) | M35: =IF($B35="","",IF($C35="ชาย",IF(J35<=VLOOKUP(F35,'เกณฑ์ส่วนสูง'!A5:U19,3,FALSE),"เตี้ย",IF(J35<=VLOOKUP(F35,'เกณฑ์ส่วนสูง'!A5:U19,5,FALSE),"ค่อนข้างเตี้ย",IF(J35<=VLOOKUP(F35,'เกณฑ์ส่วนสูง'!A5:U19,7,FALSE),"ส่วนสูงตามเกณฑ์",IF(J35<=VLOOKUP(F35,'เกณฑ์ส่วนสูง'!A5:U19,9,FALSE),"ค่อนข้างสูง","สูง")))),IF(J35<=VLOOKUP(F35,'เกณฑ์ส่วนสูง'!A5:U19,13,FALSE),"เตี้ย",IF(J35<=VLOOKUP(F35,'เกณฑ์ส่วนสูง'!A5:U19,15,FALSE),"ค่อนข้างเตี้ย",IF(J35<=VLOOKUP(F35,'เกณฑ์ส่วนสูง'!A5:U19,17,FALSE),"ส่วนสูงตามเกณฑ์",IF(J35<=VLOOKUP(F35,'เกณฑ์ส่วนสูง'!A5:U19,19,FALSE),"ค่อนข้างสูง","สูง"))))))
A36: 30 | B36: ='ข้อมูล'!C34 | C36: ='ข้อมูล'!D34 | L36: =IF($B36="","",IF($C36="ชาย",IF(K36<=VLOOKUP(F36,'เกณฑ์ดัชนีมวลกาย'!A5:U19,3,FALSE),"ผอมมาก",IF(K36<=VLOOKUP(F36,'เกณฑ์ดัชนีมวลกาย'!A5:U19,5,FALSE),"ผอม",IF(K36<=VLOOKUP(F36,'เกณฑ์ดัชนีมวลกาย'!A5:U19,7,FALSE),"สมส่วน",IF(K36<=VLOOKUP(F36,'เกณฑ์ดัชนีมวลกาย'!A5:U19,9,FALSE),"ท้วม","อ้วน")))),IF(K36<=VLOOKUP(F36,'เกณฑ์ดัชนีมวลกาย'!A5:U19,13,FALSE),"ผอมมาก",IF(K36<=VLOOKUP(F36,'เกณฑ์ดัชนีมวลกาย'!A5:U19,15,FALSE),"ผอม",IF(K36<=VLOOKUP(F36,'เกณฑ์ดัชนีมวลกาย'!A5:U19,17,FALSE),"สมส่วน",IF(K36<=VLOOKUP(F36,'เกณฑ์ดัชนีมวลกาย'!A5:U19,19,FALSE),"ท้วม","อ้วน")))))) | M36: =IF($B36="","",IF($C36="ชาย",IF(J36<=VLOOKUP(F36,'เกณฑ์ส่วนสูง'!A5:U19,3,FALSE),"เตี้ย",IF(J36<=VLOOKUP(F36,'เกณฑ์ส่วนสูง'!A5:U19,5,FALSE),"ค่อนข้างเตี้ย",IF(J36<=VLOOKUP(F36,'เกณฑ์ส่วนสูง'!A5:U19,7,FALSE),"ส่วนสูงตามเกณฑ์",IF(J36<=VLOOKUP(F36,'เกณฑ์ส่วนสูง'!A5:U19,9,FALSE),"ค่อนข้างสูง","สูง")))),IF(J36<=VLOOKUP(F36,'เกณฑ์ส่วนสูง'!A5:U19,13,FALSE),"เตี้ย",IF(J36<=VLOOKUP(F36,'เกณฑ์ส่วนสูง'!A5:U19,15,FALSE),"ค่อนข้างเตี้ย",IF(J36<=VLOOKUP(F36,'เกณฑ์ส่วนสูง'!A5:U19,17,FALSE),"ส่วนสูงตามเกณฑ์",IF(J36<=VLOOKUP(F36,'เกณฑ์ส่วนสูง'!A5:U19,19,FALSE),"ค่อนข้างสูง","สูง"))))))
B37: *** หมายเหตุ กรอกข้อมูล เฉพาะ ช่อง วันเดือนปีที่บันทึก/น้ำหนัก/ส่วนสูง เท่านั้น
B39: สรุปผล
B40: จำนวนนักเรียนทั้งหมด | C40: 17 | D40: คน
B41: จำนวนนักเรียนมีน้ำหนักสมส่วน | C41: =COUNTIF(L7:L36,"สมส่วน") -> 11 | D41: คน คิดเป็นร้อยละ | E41: =(C41*100)/C40 -> 64.705882 | F41: จำนวนนักเรียน สูงตามเกณฑ์ | I41: =COUNTIF(M7:M36,"สูง") -> 3 | J41: คน คิดเป็นร้อยละ | L41: =(I41*100)/C40 -> 17.647059
B42: จำนวนนักเรียนมีน้ำหนักอ้วน | C42: =COUNTIF(L7:L36,"อ้วน") -> 2 | D42: คน คิดเป็นร้อยละ | E42: =(C42*100)/C40 -> 11.764706 | F42: จำนวนนักเรียน สูงเกินเกณฑ์ | I42: =COUNTIF(M7:M36,"ส่วนสูงตามเกณฑ์") -> 13 | J42: คน คิดเป็นร้อยละ | L42: =(I42*100)/C40 -> 76.470588
B43: จำนวนนักเรียนมีน้ำหนักท้วม | C43: =COUNTIF(L7:L36,"ท้วม") -> 1 | D43: คน คิดเป็นร้อยละ | E43: =(C43*100)/C40 -> 5.8823529 | F43: จำนวนนักเรียน ค่อนข้างสูง | I43: =COUNTIF(M7:M36,"ค่อนข้างสูง") -> 1 | J43: คน คิดเป็นร้อยละ | L43: =(I43*100)/C40 -> 5.8823529
...

Sheet ก.พ. 66
A2: แบบบันทึกน้ำหนัก - ส่วนสูง ชั้นมัธยมศึกษาปีที่ 3 โรงเรียนบ้านหนองจอกวังกำแพง ปีการศึกษา 2565
A3: ประจำเดือน กุมภาพันธ์ พ.ศ.2566
A5: ที่ | B5: ชื่อ -นามสกุล | C5: เพศ | D5: วัน เดือน ปี | E5: วัน เดือน ปี | F5: อายุ | I5: น้ำหนัก | J5: ส่วนสูง | K5: ค่า BMI | L5: ผลการประเมิน
D6: เกิด | E6: บันทึก | F6: ปี | G6: เดือน | H6: วัน | I6: (ก.ก) | J6: (ซม.) | L6: น้ำหนัก | M6: ส่วนสูง
A7: 1 | B7: ='ข้อมูล'!C5 -> ด.ช. ห้องเรียน วิชาการ | C7: ='ข้อมูล'!D5 -> ชาย | D7: ='ข้อมูล'!E5 -> 39818 | E7: 44701 | F7: =DATEDIF(D7,E7,"y") -> 13 | G7: =DATEDIF(D7,E7,"ym") -> 4 | H7: =DATEDIF(D7,E7,"md") -> 15 | I7: 48 | J7: 165 | K7: =IF(B7="","",I7/((J7/100)^2)) -> 17.630854 | L7: =IF($B7="","",IF($C7="ชาย",IF(K7<=VLOOKUP(F7,'เกณฑ์ดัชนีมวลกาย'!A5:U19,3,FALSE),"ผอมมาก",IF(K7<=VLOOKUP(F7,'เกณฑ์ดัชนีมวลกาย'!A5:U19,5,FALSE),"ผอม",IF(K7<=VLOOKUP(F7,'เกณฑ์ดัชนีมวลกาย'!A5:U19,7,FALSE),"สมส่วน",IF(K7<=VLOOKUP(F7,'เกณฑ์ดัชนีมวลกาย'!A5:U19,9,FALSE),"ท้วม","อ้วน")))),IF(K7<=VLOOKUP(F7,'เกณฑ์ดัชนีมวลกาย'!A5:U19,13,FALSE),"ผอมมาก",IF(K7<=VLOOKUP(F7,'เกณฑ์ดัชนีมวลกาย'!A5:U19,15,FALSE),"ผอม",IF(K7<=VLOOKUP(F7,'เกณฑ์ดัชนีมวลกาย'!A5:U19,17,FALSE),"สมส่วน",IF(K7<=VLOOKUP(F7,'เกณฑ์ดัชนีมวลกาย'!A5:U19,19,FALSE),"ท้วม","อ้วน")))))) -> สมส่วน | M7: =IF($B7="","",IF($C7="ชาย",IF(J7<=VLOOKUP(F7,'เกณฑ์ส่วนสูง'!A5:U19,3,FALSE),"เตี้ย",IF(J7<=VLOOKUP(F7,'เกณฑ์ส่วนสูง'!A5:U19,5,FALSE),"ค่อนข้างเตี้ย",IF(J7<=VLOOKUP(F7,'เกณฑ์ส่วนสูง'!A5:U19,7,FALSE),"ส่วนสูงตามเกณฑ์",IF(J7<=VLOOKUP(F7,'เกณฑ์ส่วนสูง'!A5:U19,9,FALSE),"ค่อนข้างสูง","สูง")))),IF(J7<=VLOOKUP(F7,'เกณฑ์ส่วนสูง'!A5:U19,13,FALSE),"เตี้ย",IF(J7<=VLOOKUP(F7,'เกณฑ์ส่วนสูง'!A5:U19,15,FALSE),"ค่อนข้างเตี้ย",IF(J7<=VLOOKUP(F7,'เกณฑ์ส่วนสูง'!A5:U19,17,FALSE),"ส่วนสูงตามเกณฑ์",IF(J7<=VLOOKUP(F7,'เกณฑ์ส่วนสูง'!A5:U19,19,FALSE),"ค่อนข้างสูง","สูง")))))) -> ค่อนข้างสูง
A8: 2 | B8: ='ข้อมูล'!C6 -> ด.ช. ห้องเรียน วิชาการ | C8: ='ข้อมูล'!D6 -> ชาย | D8: ='ข้อมูล'!E6 -> 39942 | E8: 44701 | F8: =DATEDIF(D8,E8,"y") -> 13 | G8: =DATEDIF(D8,E8,"ym") -> 0 | H8: =DATEDIF(D8,E8,"md") -> 11 | I8: 40 | J8: 159 | K8: =IF(B8="","",I8/((J8/100)^2)) -> 15.822159 | L8: =IF($B8="","",IF($C8="ชาย",IF(K8<=VLOOKUP(F8,'เกณฑ์ดัชนีมวลกาย'!A5:U19,3,FALSE),"ผอมมาก",IF(K8<=VLOOKUP(F8,'เกณฑ์ดัชนีมวลกาย'!A5:U19,5,FALSE),"ผอม",IF(K8<=VLOOKUP(F8,'เกณฑ์ดัชนีมวลกาย'!A5:U19,7,FALSE),"สมส่วน",IF(K8<=VLOOKUP(F8,'เกณฑ์ดัชนีมวลกาย'!A5:U19,9,FALSE),"ท้วม","อ้วน")))),IF(K8<=VLOOKUP(F8,'เกณฑ์ดัชนีมวลกาย'!A5:U19,13,FALSE),"ผอมมาก",IF(K8<=VLOOKUP(F8,'เกณฑ์ดัชนีมวลกาย'!A5:U19,15,FALSE),"ผอม",IF(K8<=VLOOKUP(F8,'เกณฑ์ดัชนีมวลกาย'!A5:U19,17,FALSE),"สมส่วน",IF(K8<=VLOOKUP(F8,'เกณฑ์ดัชนีมวลกาย'!A5:U19,19,FALSE),"ท้วม","อ้วน")))))) -> ผอม | M8: =IF($B8="","",IF($C8="ชาย",IF(J8<=VLOOKUP(F8,'เกณฑ์ส่วนสูง'!A5:U19,3,FALSE),"เตี้ย",IF(J8<=VLOOKUP(F8,'เกณฑ์ส่วนสูง'!A5:U19,5,FALSE),"ค่อนข้างเตี้ย",IF(J8<=VLOOKUP(F8,'เกณฑ์ส่วนสูง'!A5:U19,7,FALSE),"ส่วนสูงตามเกณฑ์",IF(J8<=VLOOKUP(F8,'เกณฑ์ส่วนสูง'!A5:U19,9,FALSE),"ค่อนข้างสูง","สูง")))),IF(J8<=VLOOKUP(F8,'เกณฑ์ส่วนสูง'!A5:U19,13,FALSE),"เตี้ย",IF(J8<=VLOOKUP(F8,'เกณฑ์ส่วนสูง'!A5:U19,15,FALSE),"ค่อนข้างเตี้ย",IF(J8<=VLOOKUP(F8,'เกณฑ์ส่วนสูง'!A5:U19,17,FALSE),"ส่วนสูงตามเกณฑ์",IF(J8<=VLOOKUP(F8,'เกณฑ์ส่วนสูง'!A5:U19,19,FALSE),"ค่อนข้างสูง","สูง")))))) -> ส่วนสูงตามเกณฑ์
A9: 3 | B9: ='ข้อมูล'!C7 -> ด.ช. ห้องเรียน วิชาการ | C9: ='ข้อมูล'!D7 -> ชาย | D9: ='ข้อมูล'!E7 -> 39475 | E9: 44701 | F9: =DATEDIF(D9,E9,"y") -> 14 | G9: =DATEDIF(D9,E9,"ym") -> 3 | H9: =DATEDIF(D9,E9,"md") -> 22 | I9: 56 | J9: 167 | K9: =IF(B9="","",I9/((J9/100)^2)) -> 20.079601 | L9: =IF($B9="","",IF($C9="ชาย",IF(K9<=VLOOKUP(F9,'เกณฑ์ดัชนีมวลกาย'!A5:U19,3,FALSE),"ผอมมาก",IF(K9<=VLOOKUP(F9,'เกณฑ์ดัชนีมวลกาย'!A5:U19,5,FALSE),"ผอม",IF(K9<=VLOOKUP(F9,'เกณฑ์ดัชนีมวลกาย'!A5:U19,7,FALSE),"สมส่วน",IF(K9<=VLOOKUP(F9,'เกณฑ์ดัชนีมวลกาย'!A5:U19,9,FALSE),"ท้วม","อ้วน")))),IF(K9<=VLOOKUP(F9,'เกณฑ์ดัชนีมวลกาย'!A5:U19,13,FALSE),"ผอมมาก",IF(K9<=VLOOKUP(F9,'เกณฑ์ดัชนีมวลกาย'!A5:U19,15,FALSE),"ผอม",IF(K9<=VLOOKUP(F9,'เกณฑ์ดัชนีมวลกาย'!A5:U19,17,FALSE),"สมส่วน",IF(K9<=VLOOKUP(F9,'เกณฑ์ดัชนีมวลกาย'!A5:U19,19,FALSE),"ท้วม","อ้วน")))))) -> สมส่วน | M9: =IF($B9="","",IF($C9="ชาย",IF(J9<=VLOOKUP(F9,'เกณฑ์ส่วนสูง'!A5:U19,3,FALSE),"เตี้ย",IF(J9<=VLOOKUP(F9,'เกณฑ์ส่วนสูง'!A5:U19,5,FALSE),"ค่อนข้างเตี้ย",IF(J9<=VLOOKUP(F9,'เกณฑ์ส่วนสูง'!A5:U19,7,FALSE),"ส่วนสูงตามเกณฑ์",IF(J9<=VLOOKUP(F9,'เกณฑ์ส่วนสูง'!A5:U19,9,FALSE),"ค่อนข้างสูง","สูง")))),IF(J9<=VLOOKUP(F9,'เกณฑ์ส่วนสูง'!A5:U19,13,FALSE),"เตี้ย",IF(J9<=VLOOKUP(F9,'เกณฑ์ส่วนสูง'!A5:U19,15,FALSE),"ค่อนข้างเตี้ย",IF(J9<=VLOOKUP(F9,'เกณฑ์ส่วนสูง'!A5:U19,17,FALSE),"ส่วนสูงตามเกณฑ์",IF(J9<=VLOOKUP(F9,'เกณฑ์ส่วนสูง'!A5:U19,19,FALSE),"ค่อนข้างสูง","สูง")))))) -> ส่วนสูงตามเกณฑ์
A10: 4 | B10: ='ข้อมูล'!C8 -> ด.ช. ห้องเรียน วิชาการ | C10: ='ข้อมูล'!D8 -> ชาย | D10: ='ข้อมูล'!E8 -> 39895 | E10: 44701 | F10: =DATEDIF(D10,E10,"y") -> 13 | G10: =DATEDIF(D10,E10,"ym") -> 1 | H10: =DATEDIF(D10,E10,"md") -> 27 | I10: 52 | J10: 169 | K10: =IF(B10="","",I10/((J10/100)^2)) -> 18.206645 | L10: =IF($B10="","",IF($C10="ชาย",IF(K10<=VLOOKUP(F10,'เกณฑ์ดัชนีมวลกาย'!A5:U19,3,FALSE),"ผอมมาก",IF(K10<=VLOOKUP(F10,'เกณฑ์ดัชนีมวลกาย'!A5:U19,5,FALSE),"ผอม",IF(K10<=VLOOKUP(F10,'เกณฑ์ดัชนีมวลกาย'!A5:U19,7,FALSE),"สมส่วน",IF(K10<=VLOOKUP(F10,'เกณฑ์ดัชนีมวลกาย'!A5:U19,9,FALSE),"ท้วม","อ้วน")))),IF(K10<=VLOOKUP(F10,'เกณฑ์ดัชนีมวลกาย'!A5:U19,13,FALSE),"ผอมมาก",IF(K10<=VLOOKUP(F10,'เกณฑ์ดัชนีมวลกาย'!A5:U19,15,FALSE),"ผอม",IF(K10<=VLOOKUP(F10,'เกณฑ์ดัชนีมวลกาย'!A5:U19,17,FALSE),"สมส่วน",IF(K10<=VLOOKUP(F10,'เกณฑ์ดัชนีมวลกาย'!A5:U19,19,FALSE),"ท้วม","อ้วน")))))) -> สมส่วน | M10: =IF($B10="","",IF($C10="ชาย",IF(J10<=VLOOKUP(F10,'เกณฑ์ส่วนสูง'!A5:U19,3,FALSE),"เตี้ย",IF(J10<=VLOOKUP(F10,'เกณฑ์ส่วนสูง'!A5:U19,5,FALSE),"ค่อนข้างเตี้ย",IF(J10<=VLOOKUP(F10,'เกณฑ์ส่วนสูง'!A5:U19,7,FALSE),"ส่วนสูงตามเกณฑ์",IF(J10<=VLOOKUP(F10,'เกณฑ์ส่วนสูง'!A5:U19,9,FALSE),"ค่อนข้างสูง","สูง")))),IF(J10<=VLOOKUP(F10,'เกณฑ์ส่วนสูง'!A5:U19,13,FALSE),"เตี้ย",IF(J10<=VLOOKUP(F10,'เกณฑ์ส่วนสูง'!A5:U19,15,FALSE),"ค่อนข้างเตี้ย",IF(J10<=VLOOKUP(F10,'เกณฑ์ส่วนสูง'!A5:U19,17,FALSE),"ส่วนสูงตามเกณฑ์",IF(J10<=VLOOKUP(F10,'เกณฑ์ส่วนสูง'!A5:U19,19,FALSE),"ค่อนข้างสูง","สูง")))))) -> สูง
A11: 5 | B11: ='ข้อมูล'!C9 -> ด.ช. ห้องเรียน วิชาการ | C11: ='ข้อมูล'!D9 -> ชาย | D11: ='ข้อมูล'!E9 -> 39880 | E11: 44701 | F11: =DATEDIF(D11,E11,"y") -> 13 | G11: =DATEDIF(D11,E11,"ym") -> 2 | H11: =DATEDIF(D11,E11,"md") -> 12 | I11: 84 | J11: 155 | K11: =IF(B11="","",I11/((J11/100)^2)) -> 34.96358 | L11: =IF($B11="","",IF($C11="ชาย",IF(K11<=VLOOKUP(F11,'เกณฑ์ดัชนีมวลกาย'!A5:U19,3,FALSE),"ผอมมาก",IF(K11<=VLOOKUP(F11,'เกณฑ์ดัชนีมวลกาย'!A5:U19,5,FALSE),"ผอม",IF(K11<=VLOOKUP(F11,'เกณฑ์ดัชนีมวลกาย'!A5:U19,7,FALSE),"สมส่วน",IF(K11<=VLOOKUP(F11,'เกณฑ์ดัชนีมวลกาย'!A5:U19,9,FALSE),"ท้วม","อ้วน")))),IF(K11<=VLOOKUP(F11,'เกณฑ์ดัชนีมวลกาย'!A5:U19,13,FALSE),"ผอมมาก",IF(K11<=VLOOKUP(F11,'เกณฑ์ดัชนีมวลกาย'!A5:U19,15,FALSE),"ผอม",IF(K11<=VLOOKUP(F11,'เกณฑ์ดัชนีมวลกาย'!A5:U19,17,FALSE),"สมส่วน",IF(K11<=VLOOKUP(F11,'เกณฑ์ดัชนีมวลกาย'!A5:U19,19,FALSE),"ท้วม","อ้วน")))))) -> อ้วน | M11: =IF($B11="","",IF($C11="ชาย",IF(J11<=VLOOKUP(F11,'เกณฑ์ส่วนสูง'!A5:U19,3,FALSE),"เตี้ย",IF(J11<=VLOOKUP(F11,'เกณฑ์ส่วนสูง'!A5:U19,5,FALSE),"ค่อนข้างเตี้ย",IF(J11<=VLOOKUP(F11,'เกณฑ์ส่วนสูง'!A5:U19,7,FALSE),"ส่วนสูงตามเกณฑ์",IF(J11<=VLOOKUP(F11,'เกณฑ์ส่วนสูง'!A5:U19,9,FALSE),"ค่อนข้างสูง","สูง")))),IF(J11<=VLOOKUP(F11,'เกณฑ์ส่วนสูง'!A5:U19,13,FALSE),"เตี้ย",IF(J11<=VLOOKUP(F11,'เกณฑ์ส่วนสูง'!A5:U19,15,FALSE),"ค่อนข้างเตี้ย",IF(J11<=VLOOKUP(F11,'เกณฑ์ส่วนสูง'!A5:U19,17,FALSE),"ส่วนสูงตามเกณฑ์",IF(J11<=VLOOKUP(F11,'เกณฑ์ส่วนสูง'!A5:U19,19,FALSE),"ค่อนข้างสูง","สูง")))))) -> ส่วนสูงตามเกณฑ์
A12: 6 | B12: ='ข้อมูล'!C10 -> ด.ช. ห้องเรียน วิชาการ | C12: ='ข้อมูล'!D10 -> ชาย | D12: ='ข้อมูล'!E10 -> 39735 | E12: 44701 | F12: =DATEDIF(D12,E12,"y") -> 13 | G12: =DATEDIF(D12,E12,"ym") -> 7 | H12: =DATEDIF(D12,E12,"md") -> 6 | I12: 70 | J12: 167 | K12: =IF(B12="","",I12/((J12/100)^2)) -> 25.099502 | L12: =IF($B12="","",IF($C12="ชาย",IF(K12<=VLOOKUP(F12,'เกณฑ์ดัชนีมวลกาย'!A5:U19,3,FALSE),"ผอมมาก",IF(K12<=VLOOKUP(F12,'เกณฑ์ดัชนีมวลกาย'!A5:U19,5,FALSE),"ผอม",IF(K12<=VLOOKUP(F12,'เกณฑ์ดัชนีมวลกาย'!A5:U19,7,FALSE),"สมส่วน",IF(K12<=VLOOKUP(F12,'เกณฑ์ดัชนีมวลกาย'!A5:U19,9,FALSE),"ท้วม","อ้วน")))),IF(K12<=VLOOKUP(F12,'เกณฑ์ดัชนีมวลกาย'!A5:U19,13,FALSE),"ผอมมาก",IF(K12<=VLOOKUP(F12,'เกณฑ์ดัชนีมวลกาย'!A5:U19,15,FALSE),"ผอม",IF(K12<=VLOOKUP(F12,'เกณฑ์ดัชนีมวลกาย'!A5:U19,17,FALSE),"สมส่วน",IF(K12<=VLOOKUP(F12,'เกณฑ์ดัชนีมวลกาย'!A5:U19,19,FALSE),"ท้วม","อ้วน")))))) -> ท้วม | M12: =IF($B12="","",IF($C12="ชาย",IF(J12<=VLOOKUP(F12,'เกณฑ์ส่วนสูง'!A5:U19,3,FALSE),"เตี้ย",IF(J12<=VLOOKUP(F12,'เกณฑ์ส่วนสูง'!A5:U19,5,FALSE),"ค่อนข้างเตี้ย",IF(J12<=VLOOKUP(F12,'เกณฑ์ส่วนสูง'!A5:U19,7,FALSE),"ส่วนสูงตามเกณฑ์",IF(J12<=VLOOKUP(F12,'เกณฑ์ส่วนสูง'!A5:U19,9,FALSE),"ค่อนข้างสูง","สูง")))),IF(J12<=VLOOKUP(F12,'เกณฑ์ส่วนสูง'!A5:U19,13,FALSE),"เตี้ย",IF(J12<=VLOOKUP(F12,'เกณฑ์ส่วนสูง'!A5:U19,15,FALSE),"ค่อนข้างเตี้ย",IF(J12<=VLOOKUP(F12,'เกณฑ์ส่วนสูง'!A5:U19,17,FALSE),"ส่วนสูงตามเกณฑ์",IF(J12<=VLOOKUP(F12,'เกณฑ์ส่วนสูง'!A5:U19,19,FALSE),"ค่อนข้างสูง","สูง")))))) -> ค่อนข้างสูง
A13: 7 | B13: ='ข้อมูล'!C11 -> ด.ช. ห้องเรียน วิชาการ | C13: ='ข้อมูล'!D11 -> ชาย | D13: ='ข้อมูล'!E11 -> 39767 | E13: 44701 | F13: =DATEDIF(D13,E13,"y") -> 13 | G13: =DATEDIF(D13,E13,"ym") -> 6 | H13: =DATEDIF(D13,E13,"md") -> 5 | K13: =IF(B13="","",I13/((J13/100)^2)) -> #DIV/0! | L13: =IF($B13="","",IF($C13="ชาย",IF(K13<=VLOOKUP(F13,'เกณฑ์ดัชนีมวลกาย'!A5:U19,3,FALSE),"ผอมมาก",IF(K13<=VLOOKUP(F13,'เกณฑ์ดัชนีมวลกาย'!A5:U19,5,FALSE),"ผอม",IF(K13<=VLOOKUP(F13,'เกณฑ์ดัชนีมวลกาย'!A5:U19,7,FALSE),"สมส่วน",IF(K13<=VLOOKUP(F13,'เกณฑ์ดัชนีมวลกาย'!A5:U19,9,FALSE),"ท้วม","อ้วน")))),IF(K13<=VLOOKUP(F13,'เกณฑ์ดัชนีมวลกาย'!A5:U19,13,FALSE),"ผอมมาก",IF(K13<=VLOOKUP(F13,'เกณฑ์ดัชนีมวลกาย'!A5:U19,15,FALSE),"ผอม",IF(K13<=VLOOKUP(F13,'เกณฑ์ดัชนีมวลกาย'!A5:U19,17,FALSE),"สมส่วน",IF(K13<=VLOOKUP(F13,'เกณฑ์ดัชนีมวลกาย'!A5:U19,19,FALSE),"ท้วม","อ้วน")))))) -> #DIV/0! | M13: =IF($B13="","",IF($C13="ชาย",IF(J13<=VLOOKUP(F13,'เกณฑ์ส่วนสูง'!A5:U19,3,FALSE),"เตี้ย",IF(J13<=VLOOKUP(F13,'เกณฑ์ส่วนสูง'!A5:U19,5,FALSE),"ค่อนข้างเตี้ย",IF(J13<=VLOOKUP(F13,'เกณฑ์ส่วนสูง'!A5:U19,7,FALSE),"ส่วนสูงตามเกณฑ์",IF(J13<=VLOOKUP(F13,'เกณฑ์ส่วนสูง'!A5:U19,9,FALSE),"ค่อนข้างสูง","สูง")))),IF(J13<=VLOOKUP(F13,'เกณฑ์ส่วนสูง'!A5:U19,13,FALSE),"เตี้ย",IF(J13<=VLOOKUP(F13,'เกณฑ์ส่วนสูง'!A5:U19,15,FALSE),"ค่อนข้างเตี้ย",IF(J13<=VLOOKUP(F13,'เกณฑ์ส่วนสูง'!A5:U19,17,FALSE),"ส่วนสูงตามเกณฑ์",IF(J13<=VLOOKUP(F13,'เกณฑ์ส่วนสูง'!A5:U19,19,FALSE),"ค่อนข้างสูง","สูง")))))) -> เตี้ย
A14: 8 | B14: ='ข้อมูล'!C12 -> ด.ช. ห้องเรียน วิชาการ | C14: ='ข้อมูล'!D12 -> ชาย | D14: ='ข้อมูล'!E12 -> 39612 | E14: 44701 | F14: =DATEDIF(D14,E14,"y") -> 13 | G14: =DATEDIF(D14,E14,"ym") -> 11 | H14: =DATEDIF(D14,E14,"md") -> 7 | K14: =IF(B14="","",I14/((J14/100)^2)) -> #DIV/0! | L14: =IF($B14="","",IF($C14="ชาย",IF(K14<=VLOOKUP(F14,'เกณฑ์ดัชนีมวลกาย'!A5:U19,3,FALSE),"ผอมมาก",IF(K14<=VLOOKUP(F14,'เกณฑ์ดัชนีมวลกาย'!A5:U19,5,FALSE),"ผอม",IF(K14<=VLOOKUP(F14,'เกณฑ์ดัชนีมวลกาย'!A5:U19,7,FALSE),"สมส่วน",IF(K14<=VLOOKUP(F14,'เกณฑ์ดัชนีมวลกาย'!A5:U19,9,FALSE),"ท้วม","อ้วน")))),IF(K14<=VLOOKUP(F14,'เกณฑ์ดัชนีมวลกาย'!A5:U19,13,FALSE),"ผอมมาก",IF(K14<=VLOOKUP(F14,'เกณฑ์ดัชนีมวลกาย'!A5:U19,15,FALSE),"ผอม",IF(K14<=VLOOKUP(F14,'เกณฑ์ดัชนีมวลกาย'!A5:U19,17,FALSE),"สมส่วน",IF(K14<=VLOOKUP(F14,'เกณฑ์ดัชนีมวลกาย'!A5:U19,19,FALSE),"ท้วม","อ้วน")))))) -> #DIV/0! | M14: =IF($B14="","",IF($C14="ชาย",IF(J14<=VLOOKUP(F14,'เกณฑ์ส่วนสูง'!A5:U19,3,FALSE),"เตี้ย",IF(J14<=VLOOKUP(F14,'เกณฑ์ส่วนสูง'!A5:U19,5,FALSE),"ค่อนข้างเตี้ย",IF(J14<=VLOOKUP(F14,'เกณฑ์ส่วนสูง'!A5:U19,7,FALSE),"ส่วนสูงตามเกณฑ์",IF(J14<=VLOOKUP(F14,'เกณฑ์ส่วนสูง'!A5:U19,9,FALSE),"ค่อนข้างสูง","สูง")))),IF(J14<=VLOOKUP(F14,'เกณฑ์ส่วนสูง'!A5:U19,13,FALSE),"เตี้ย",IF(J14<=VLOOKUP(F14,'เกณฑ์ส่วนสูง'!A5:U19,15,FALSE),"ค่อนข้างเตี้ย",IF(J14<=VLOOKUP(F14,'เกณฑ์ส่วนสูง'!A5:U19,17,FALSE),"ส่วนสูงตามเกณฑ์",IF(J14<=VLOOKUP(F14,'เกณฑ์ส่วนสูง'!A5:U19,19,FALSE),"ค่อนข้างสูง","สูง")))))) -> เตี้ย
A15: 9 | B15: ='ข้อมูล'!C13 -> ด.ช. ห้องเรียน วิชาการ | C15: ='ข้อมูล'!D13 -> ชาย | D15: ='ข้อมูล'!E13 -> 39930 | E15: 44701 | F15: =DATEDIF(D15,E15,"y") -> 13 | G15: =DATEDIF(D15,E15,"ym") -> 0 | H15: =DATEDIF(D15,E15,"md") -> 23 | K15: =IF(B15="","",I15/((J15/100)^2)) -> #DIV/0! | L15: =IF($B15="","",IF($C15="ชาย",IF(K15<=VLOOKUP(F15,'เกณฑ์ดัชนีมวลกาย'!A5:U19,3,FALSE),"ผอมมาก",IF(K15<=VLOOKUP(F15,'เกณฑ์ดัชนีมวลกาย'!A5:U19,5,FALSE),"ผอม",IF(K15<=VLOOKUP(F15,'เกณฑ์ดัชนีมวลกาย'!A5:U19,7,FALSE),"สมส่วน",IF(K15<=VLOOKUP(F15,'เกณฑ์ดัชนีมวลกาย'!A5:U19,9,FALSE),"ท้วม","อ้วน")))),IF(K15<=VLOOKUP(F15,'เกณฑ์ดัชนีมวลกาย'!A5:U19,13,FALSE),"ผอมมาก",IF(K15<=VLOOKUP(F15,'เกณฑ์ดัชนีมวลกาย'!A5:U19,15,FALSE),"ผอม",IF(K15<=VLOOKUP(F15,'เกณฑ์ดัชนีมวลกาย'!A5:U19,17,FALSE),"สมส่วน",IF(K15<=VLOOKUP(F15,'เกณฑ์ดัชนีมวลกาย'!A5:U19,19,FALSE),"ท้วม","อ้วน")))))) -> #DIV/0! | M15: =IF($B15="","",IF($C15="ชาย",IF(J15<=VLOOKUP(F15,'เกณฑ์ส่วนสูง'!A5:U19,3,FALSE),"เตี้ย",IF(J15<=VLOOKUP(F15,'เกณฑ์ส่วนสูง'!A5:U19,5,FALSE),"ค่อนข้างเตี้ย",IF(J15<=VLOOKUP(F15,'เกณฑ์ส่วนสูง'!A5:U19,7,FALSE),"ส่วนสูงตามเกณฑ์",IF(J15<=VLOOKUP(F15,'เกณฑ์ส่วนสูง'!A5:U19,9,FALSE),"ค่อนข้างสูง","สูง")))),IF(J15<=VLOOKUP(F15,'เกณฑ์ส่วนสูง'!A5:U19,13,FALSE),"เตี้ย",IF(J15<=VLOOKUP(F15,'เกณฑ์ส่วนสูง'!A5:U19,15,FALSE),"ค่อนข้างเตี้ย",IF(J15<=VLOOKUP(F15,'เกณฑ์ส่วนสูง'!A5:U19,17,FALSE),"ส่วนสูงตามเกณฑ์",IF(J15<=VLOOKUP(F15,'เกณฑ์ส่วนสูง'!A5:U19,19,FALSE),"ค่อนข้างสูง","สูง")))))) -> เตี้ย
A16: 10 | B16: ='ข้อมูล'!C14 -> ด.ญ.ห้องเรียน วิชาการ | C16: ='ข้อมูล'!D14 -> หญิง | D16: ='ข้อมูล'!E14 -> 39687 | E16: 44701 | F16: =DATEDIF(D16,E16,"y") -> 13 | G16: =DATEDIF(D16,E16,"ym") -> 8 | H16: =DATEDIF(D16,E16,"md") -> 23 | K16: =IF(B16="","",I16/((J16/100)^2)) -> #DIV/0! | L16: =IF($B16="","",IF($C16="ชาย",IF(K16<=VLOOKUP(F16,'เกณฑ์ดัชนีมวลกาย'!A5:U19,3,FALSE),"ผอมมาก",IF(K16<=VLOOKUP(F16,'เกณฑ์ดัชนีมวลกาย'!A5:U19,5,FALSE),"ผอม",IF(K16<=VLOOKUP(F16,'เกณฑ์ดัชนีมวลกาย'!A5:U19,7,FALSE),"สมส่วน",IF(K16<=VLOOKUP(F16,'เกณฑ์ดัชนีมวลกาย'!A5:U19,9,FALSE),"ท้วม","อ้วน")))),IF(K16<=VLOOKUP(F16,'เกณฑ์ดัชนีมวลกาย'!A5:U19,13,FALSE),"ผอมมาก",IF(K16<=VLOOKUP(F16,'เกณฑ์ดัชนีมวลกาย'!A5:U19,15,FALSE),"ผอม",IF(K16<=VLOOKUP(F16,'เกณฑ์ดัชนีมวลกาย'!A5:U19,17,FALSE),"สมส่วน",IF(K16<=VLOOKUP(F16,'เกณฑ์ดัชนีมวลกาย'!A5:U19,19,FALSE),"ท้วม","อ้วน")))))) -> #DIV/0! | M16: =IF($B16="","",IF($C16="ชาย",IF(J16<=VLOOKUP(F16,'เกณฑ์ส่วนสูง'!A5:U19,3,FALSE),"เตี้ย",IF(J16<=VLOOKUP(F16,'เกณฑ์ส่วนสูง'!A5:U19,5,FALSE),"ค่อนข้างเตี้ย",IF(J16<=VLOOKUP(F16,'เกณฑ์ส่วนสูง'!A5:U19,7,FALSE),"ส่วนสูงตามเกณฑ์",IF(J16<=VLOOKUP(F16,'เกณฑ์ส่วนสูง'!A5:U19,9,FALSE),"ค่อนข้างสูง","สูง")))),IF(J16<=VLOOKUP(F16,'เกณฑ์ส่วนสูง'!A5:U19,13,FALSE),"เตี้ย",IF(J16<=VLOOKUP(F16,'เกณฑ์ส่วนสูง'!A5:U19,15,FALSE),"ค่อนข้างเตี้ย",IF(J16<=VLOOKUP(F16,'เกณฑ์ส่วนสูง'!A5:U19,17,FALSE),"ส่วนสูงตามเกณฑ์",IF(J16<=VLOOKUP(F16,'เกณฑ์ส่วนสูง'!A5:U19,19,FALSE),"ค่อนข้างสูง","สูง")))))) -> เตี้ย
A17: 11 | B17: ='ข้อมูล'!C15 -> ด.ญ.ห้องเรียน วิชาการ | C17: ='ข้อมูล'!D15 -> หญิง | D17: ='ข้อมูล'!E15 -> 39234 | E17: 44701 | F17: =DATEDIF(D17,E17,"y") -> 14 | G17: =DATEDIF(D17,E17,"ym") -> 11 | H17: =DATEDIF(D17,E17,"md") -> 19 | K17: =IF(B17="","",I17/((J17/100)^2)) -> #DIV/0! | L17: =IF($B17="","",IF($C17="ชาย",IF(K17<=VLOOKUP(F17,'เกณฑ์ดัชนีมวลกาย'!A5:U19,3,FALSE),"ผอมมาก",IF(K17<=VLOOKUP(F17,'เกณฑ์ดัชนีมวลกาย'!A5:U19,5,FALSE),"ผอม",IF(K17<=VLOOKUP(F17,'เกณฑ์ดัชนีมวลกาย'!A5:U19,7,FALSE),"สมส่วน",IF(K17<=VLOOKUP(F17,'เกณฑ์ดัชนีมวลกาย'!A5:U19,9,FALSE),"ท้วม","อ้วน")))),IF(K17<=VLOOKUP(F17,'เกณฑ์ดัชนีมวลกาย'!A5:U19,13,FALSE),"ผอมมาก",IF(K17<=VLOOKUP(F17,'เกณฑ์ดัชนีมวลกาย'!A5:U19,15,FALSE),"ผอม",IF(K17<=VLOOKUP(F17,'เกณฑ์ดัชนีมวลกาย'!A5:U19,17,FALSE),"สมส่วน",IF(K17<=VLOOKUP(F17,'เกณฑ์ดัชนีมวลกาย'!A5:U19,19,FALSE),"ท้วม","อ้วน")))))) -> #DIV/0! | M17: =IF($B17="","",IF($C17="ชาย",IF(J17<=VLOOKUP(F17,'เกณฑ์ส่วนสูง'!A5:U19,3,FALSE),"เตี้ย",IF(J17<=VLOOKUP(F17,'เกณฑ์ส่วนสูง'!A5:U19,5,FALSE),"ค่อนข้างเตี้ย",IF(J17<=VLOOKUP(F17,'เกณฑ์ส่วนสูง'!A5:U19,7,FALSE),"ส่วนสูงตามเกณฑ์",IF(J17<=VLOOKUP(F17,'เกณฑ์ส่วนสูง'!A5:U19,9,FALSE),"ค่อนข้างสูง","สูง")))),IF(J17<=VLOOKUP(F17,'เกณฑ์ส่วนสูง'!A5:U19,13,FALSE),"เตี้ย",IF(J17<=VLOOKUP(F17,'เกณฑ์ส่วนสูง'!A5:U19,15,FALSE),"ค่อนข้างเตี้ย",IF(J17<=VLOOKUP(F17,'เกณฑ์ส่วนสูง'!A5:U19,17,FALSE),"ส่วนสูงตามเกณฑ์",IF(J17<=VLOOKUP(F17,'เกณฑ์ส่วนสูง'!A5:U19,19,FALSE),"ค่อนข้างสูง","สูง")))))) -> เตี้ย
